Workbook

Sheet Instructions
B2: The MEDEVAC Tracker is used to track MEDEVAC missions and their corresponding obligation, origin/destination, agency, etc. for all patients MEDEVACed by the Bureau of Medical Services. There are 6 primary tabs:
B4: 1) The MEDEVAC Case Summary tab provides quick reference data and visualizaitons on MEDEVAC cases, types, amendments, obligation amounts, etc. to analyze which regions/posts require relatively more MEDEVACs and why, how often they are amended/extended and for how long, the duration of MEDEVACs, etc.
B6: 2) The MEDEVAC Case Log tab provides a space to track cables as they come in and need to be processed. This tab is not meant to store data long term but should be added to the other tabs once processed.
B8: 3) The MEDEVACs tab is used to store all MEDEVAC related data for reach mission and its corresponding amendments and extensions as applcable.
B10: 4) The Additional Traveler Calculator tab provides a calculation of the total per diem authorized for each additional traveler.
B12: Additionally, lists can be accessed and amended on the hidden Lists tab.
B15: To maintain data integrity, columns which use a formula have been locked. The password is MEDEVAC.

Sheet MEDEVAC Case Log
D2: CABLE INBOX CHECKED | E2: DATE | F2: TIME | G2: Cable # | H2: Budget Codes for MEDEVAC
C3: LS | E3: 45212 | F3: 0.34444444 | G3: 23 STATE 110530
C5: Cable Tracker
C6: Budget Employee | D6: STATUS (Describe and sign in Budget Employee for note) | E6: Obligation Number | F6: Patient Name | G6: Cable # | H6: Cable Date | I6: MEDEVAC Type | J6: Cable Type
F8: USE NEW CASE LOG FY24

Sheet FY2023 MEDEVAC Tracker
B3: LOOKUP
B4: MEDEVAC Status | C4: Cable Status | D4: Obligation Number | E4: MSG, DOS, or Seabee | F4: Patient Name | G4: Total Obligation | H4: Start Date | I4: End Date | J4: MEDEVAC Type | K4: Traveler Type | L4: Employee Status or Name | M4: Region | N4: Home Post | O4: MEDEVAC Location | P4: Route (CONUS/OCONUS) | Q4: Number of Amendments | R4: Total Extension Duration
B5: #N/A | C5: Cable Status | D5: Obligation Number | E5: MSG, DOS, or Seabee | F5: Patient Name | G5: Total Obligation | H5: Start Date | I5: End Date | J5: MEDEVAC Type | K5: Traveler Type | L5: Employee Status or Name | M5: Region | N5: Home Post | O5: MEDEVAC Location | P5: Route (CONUS/OCONUS) | Q5: Number of Amendments | R5: Duration of Extensions
B7: MEDEVAC Status | C7: Cable Status | D7: Obligation Number | E7: MSG, DOS, or Seabee | F7: Patient Name | G7: Total Obligation | H7: Start Date | I7: End Date | J7: MEDEVAC Type | K7: Traveler Type | L7: Employee Status or Name | M7: Region | N7: Home Post | O7: MEDEVAC Location | P7: Route (CONUS/OCONUS) | Q7: Number of Amendments | R7: Duration of Extensions | S7: Initial Start Date | T7: Initial End Date | U7: Number of Days | V7: Initial MEDEVAC Location | W7: Funding Cable In Date | X7: Funding Cable Sent Date | Y7: BD Employee | Z7: Employee Response Time | AA7: 1st Per Diem Rate | AB7: # of Days at | AC7: 2nd Per Diem Rate | AD7: # of Days at2 | AE7: 3rd Per Diem Rate | AF7: # of Days at3 | AG7: 4th Per Diem Rate | AH7: # of Days at4 | AI7: Airfare | AJ7: Total Per Diem - Patient | AK7: Total Per Diem - Additional Travelers | AL7: Misc. Expenses | AM7: Total Per Diem | AN7: Initial Funding Total | AO7: A1 - Amended Start Date | AP7: A1 - Amended End Date | AQ7: A1 - Amendment Funding Cable In Date | AR7: A1 - Amendment Funding Cable Out Date | AS7: A1 - BD Employee | AT7: A1 - Employee Response Time | AU7: A1 - Amended MEDEVAC Location | AV7: A1 - 1st Per Diem Rate (Lodging + M&IE) | AW7: A1 - # of Days At 1st Per Diem Rate | AX7: A1 - 2nd Per Diem Rate (Lodging + M&IE) | AY7: A1 - # of Days At 2nd Per Diem Rate | AZ7: A1 - 3rd Per Diem Rate (Lodging + M&IE) | BA7: A1 - # of Days At 3rd Per Diem Rate | BB7: A1 - 4th Per Diem Rate (Lodging + M&IE) | BC7: A1 - # of Days At 4th Per Diem Rate | BD7: A1 - Airfare | BE7: A1 - Total Per Diem Additional Travelers | BF7: A1 - Misc. Expenses | BG7: A1 - Airfare Amount for Obligation | BH7: A1 - Per Diem Amount for Obligation | BI7: A1 - New Obligation Total | BJ7: E1 - Extension End Date | BK7: E1 - Extension Funding Cable In Date | BL7: E1 - Extension Funding Cable Out Date | BM7: E1 - BD Employee | BN7: E1 - Employee Response Time | BO7: E1 - MEDEVAC Location | BP7: E1 - 1st Per Diem Rate (Lodging + M&IE) | BQ7: E1 - # of Days At 1st Per Diem Rate | BR7: E1 - 2nd Per Diem Rate (Lodging + M&IE) | BS7: E1 - # of Days At 2nd Per Diem Rate | BT7: E1 - 3rd Per Diem Rate (Lodging + M&IE) | BU7: E1 - # of Days At 3rd Per Diem Rate | BV7: 4th Per Diem Rate (Lodging + M&IE) | BW7: E1 - # of Days At 4th Per Diem Rate | BX7: E1 - Airfare | BY7: E1 - Total Per Diem Additional Travelers | BZ7: E1 - Additional Per Diem Amount | CA7: E1 - Extension Funding Total | CB7: E2 - Extension End Date | CC7: E2 - Extension Funding Cable In Date | CD7: E2 - Extension Funding Cable Out Date | CE7: E2 - BD Employee | CF7: E2 - Employee Response Time | CG7: E2 MEDEVAC Location | CH7: E2 - 1st Per Diem Rate (Lodging + M&IE) | CI7: E2 - # of Days At 1st Per Diem Rate | CJ7: E2 - 2nd Per Diem Rate (Lodging + M&IE) | CK7: E2 - # of Days At E2 - 2nd Per Diem Rate | CL7: 3rd Per Diem Rate (Lodging + M&IE) | CM7: E2 - # of Days At 3rd Per Diem Rate | CN7: E2 - 4th Per Diem Rate (Lodging + M&IE) | CO7: E2 - # of Days At 4th Per Diem Rate | CP7: E2 - Airfare | CQ7: E2 - Total Per Diem Additional Travelers | CR7: E2 - Additional Per Diem Amount | CS7: E2 - Extension Funding Total | CT7: E3 - Extension End Date | CU7: E3 - Extension Funding Cable In Date | CV7: E3 - Extension Funding Cable Out Date | CW7: E3 - BD Employee | CX7: E3 - Employee Response Time | CY7: E3 - MEDEVAC Location | CZ7: E3 - 1st Per Diem Rate (Lodging + M&IE) | DA7: E3 - # of Days At 1st Per Diem Rate | DB7: E3 - 2nd Per Diem Rate (Lodging + M&IE) | DC7: E3 - # of Days At E3 - 2nd Per Diem Rate | DD7: E3 - 3rd Per Diem Rate (Lodging + M&IE) | DE7: E3 - # of Days At 3rd Per Diem Rate | DF7: E3 - 4th Per Diem Rate (Lodging + M&IE) | DG7: E3 - # of Days At 4th Per Diem Rate | DH7: E3 - Airfare | DI7: E3 - Total Per Diem E3 - Additional Travelers | DJ7: E3 - Additional Per Diem Amount | DK7: E3 - Extension Funding Total | DL7: E4 - Extension End Date | DM7: E4 - Extension Funding Cable In Date | DN7: E4 - Extension Funding Cable Out Date | DO7: E4 - BD Employee | DP7: E4 - Employee Response Time | DQ7: E4 - MEDEVAC Location | DR7: 1st Per Diem Rate (Lodging + M&IE) | DS7: E4 - # of Days At 1st Per Diem Rate | DT7: E4 - 2nd Per Diem Rate (Lodging + M&IE) | DU7: E4 - # of Days At E4 - 2nd Per Diem Rate | DV7: E4 - 3rd Per Diem Rate (Lodging + M&IE) | DW7: E4 - # of Days At 3rd Per Diem Rate | DX7: E4 - 4th Per Diem Rate (Lodging + M&IE) | DY7: E4 - # of Days At 4th Per Diem Rate | DZ7: E4 - Airfare | EA7: E4 - Total Per Diem Additional Travelers | EB7: E4 - Additional Per Diem Amount | EC7: E4 - Extension Funding Total | ED7: E5 - Extension End Date | EE7: E5 - Extension Funding Cable In Date | EF7: E5 - Extension Funding Cable Out Date | EG7: E5 - BD Employee | EH7: E5 - Employee Response Time | EI7: E5 - MEDEVAC Location | EJ7: E5 - 1st Per Diem Rate (Lodging + M&IE) | EK7: E5 - # of Days At 1st Per Diem Rate | EL7: E5 - 2nd Per Diem Rate (Lodging + M&IE) | EM7: E5 - # of Days At E5 - 2nd Per Diem Rate | EN7: E5 - 3rd Per Diem Rate (Lodging + M&IE) | EO7: E5 - # of Days At 3rd Per Diem Rate | EP7: E5 -4th Per Diem Rate (Lodging + M&IE) | EQ7: E5 - # of Days At 4th Per Diem Rate | ER7: E5 - Airfare | ES7: E5 - Total Per Diem Additional Travelers | ET7: E5 - Additional Per Diem Amount | EU7: E5 - Extension Funding Total | EV7: E6 - Extension End Date | EW7: E6 - Extension Funding Cable In Date | EX7: E6 - Extension Funding Cable Out Date | EY7: E6 - BD Employee | EZ7: E6 - Employee Response Time | FA7: E6 - MEDEVAC Location | FB7: E6 - 1st Per Diem Rate (Lodging + M&IE) | FC7: E6 - # of Days At 1st Per Diem Rate | FD7: E6 - 2nd Per Diem Rate (Lodging + M&IE) | FE7: E6 - # of Days At E6 - 2nd Per Diem Rate | FF7: E6 - 3rd Per Diem Rate (Lodging + M&IE) | FG7: E6 - # of Days At 3rd Per Diem Rate | FH7: E6 -4th Per Diem Rate (Lodging + M&IE) | FI7: E6 - # of Days At 4th Per Diem Rate | FJ7: E6 - Airfare | FK7: E6 - Total Per Diem Additional Travelers | FL7: E6 - Additional Per Diem Amount | FM7: E6 - Extension Funding Total | FN7: E7 - Extension End Date | FO7: E7 - Extension Funding Cable In Date | FP7: E7 - Extension Funding Cable Out Date | FQ7: E7 - BD Employee | FR7: E7 - Employee Response Time | FS7: E7 - MEDEVAC Location | FT7: E7 - 1st Per Diem Rate (Lodging + M&IE) | FU7: E7 - # of Days At 1st Per Diem Rate | FV7: E7 - 2nd Per Diem Rate (Lodging + M&IE) | FW7: E7 - # of Days At E7 - 2nd Per Diem Rate | FX7: E7 - 3rd Per Diem Rate (Lodging + M&IE) | FY7: E7 - # of Days At 3rd Per Diem Rate | FZ7: E7 -4th Per Diem Rate (Lodging + M&IE) | GA7: E7 - # of Days At 4th Per Diem Rate | GB7: E7 - Airfare | GC7: E7 - Total Per Diem Additional Travelers | GD7: E7 - Additional Per Diem Amount | GE7: E7 - Extension Funding Total | GF7: E8 - Extension End Date | GG7: E8 - Extension Funding Cable In Date | GH7: E8 - Extension Funding Cable Out Date | GI7: E8 - BD Employee | GJ7: E8 - Employee Response Time | GK7: E8 - MEDEVAC Location | GL7: E8 - 1st Per Diem Rate (Lodging + M&IE) | GM7: E8 - # of Days At 1st Per Diem Rate | GN7: E8 - 2nd Per Diem Rate (Lodging + M&IE) | GO7: E8 - # of Days At E8 - 2nd Per Diem Rate | GP7: E8 - 3rd Per Diem Rate (Lodging + M&IE) | GQ7: E8 - # of Days At 3rd Per Diem Rate | GR7: E8 -4th Per Diem Rate (Lodging + M&IE) | GS7: E8 - # of Days At 4th Per Diem Rate | GT7: E8 - Airfare | GU7: E8 - Total Per Diem Additional Travelers | GV7: E8 - Additional Per Diem Amount | GW7: E8 - Extension Funding Total | GX7: E9 - Extension End Date | GY7: E9 - Extension Funding Cable In Date | GZ7: E9 - Extension Funding Cable Out Date | HA7: E9 - BD Employee | HB7: E9 - Employee Response Time | HC7: E9 - MEDEVAC Location | HD7: E9 - 1st Per Diem Rate (Lodging + M&IE) | HE7: E9 - # of Days At 1st Per Diem Rate | HF7: E9 - 2nd Per Diem Rate (Lodging + M&IE) | HG7: E9 - # of Days At E9 - 2nd Per Diem Rate | HH7: E9 - 3rd Per Diem Rate (Lodging + M&IE) | HI7: E9 - # of Days At 3rd Per Diem Rate | HJ7: E9 -4th Per Diem Rate (Lodging + M&IE) | HK7: E9 - # of Days At 4th Per Diem Rate | HL7: E9 - Airfare | HM7: E9 - Total Per Diem Additional Travelers | HN7: E9 - Additional Per Diem Amount | HO7: E9 - Extension Funding Total | HP7: E10 - Extension End Date | HQ7: E10 - Extension Funding Cable In Date | HR7: E10 - Extension Funding Cable Out Date | HS7: E10 - BD Employee | HT7: E10 - Employee Response Time | HU7: E10 - MEDEVAC Location | HV7: E10 - 1st Per Diem Rate (Lodging + M&IE) | HW7: E10 - # of Days At 1st Per Diem Rate | HX7: E10 - 2nd Per Diem Rate (Lodging + M&IE) | HY7: E10 - # of Days At E10 - 2nd Per Diem Rate | HZ7: E10 - 3rd Per Diem Rate (Lodging + M&IE) | IA7: E10 - # of Days At 3rd Per Diem Rate | IB7: E10 -4th Per Diem Rate (Lodging + M&IE) | IC7: E10 - # of Days At 4th Per Diem Rate | ID7: E10 - Airfare | IE7: E10 - Total Per Diem Additional Travelers | IF7: E10 - Additional Per Diem Amount | IG7: E10 - Extension Funding Total | IH7: Completion Status | II7: Date of Final Accounting | IJ7: Actual Start Date | IK7: Actual End Date | IL7: Airfare Approved | IM7: Per Diem Approved | IN7: Closed Amount | IO7: Amount for Deobligation | IP7: Comments | IQ7: Date to send Request for Final Accounting (FA)
B8: =IF(NOT(ISBLANK('FY2023 MEDEVAC Tracker'!$IH8)), IH8, IF(NOT(ISBLANK('FY2023 MEDEVAC Tracker'!$HR8)), "10th Extension Funding Out", IF(NOT(ISBLANK('FY2023 MEDEVAC Tracker'!$GZ8)), "9th Extension Funding Out", IF(NOT(ISBLANK('FY2023 MEDEVAC Tracker'!$GH8)), "8th Extension Funding Out", IF(NOT(ISBLANK('FY2023 MEDEVAC Tracker'!$FP8)), "7th Extension Funding Out", IF(NOT(ISBLANK('FY2023 MEDEVAC Tracker'!$EX8)), "6th Extension Funding Out", IF(NOT(ISBLANK('FY2023 MEDEVAC Tracker'!$EF8)), "5th Extension Funding Out", IF(NOT(ISBLANK('FY2023 MEDEVAC Tracker'!$EE8)), "5th Extension In Processing", IF(NOT(ISBLANK('FY2023 MEDEVAC Tracker'!$DN8)), "4th Extension Funding Out", IF(NOT(ISBLANK('FY2023 MEDEVAC Tracker'!$DM8)), "4th Extension In Processing",IF(NOT(ISBLANK('FY2023 MEDEVAC Tracker'!$CV8)), "3rd Extension Funding Out", IF(NOT(ISBLANK('FY2023 MEDEVAC Tracker'!$CU8)), "3rd Extension In Processing", IF(NOT(ISBLANK('FY2023 MEDEVAC Tracker'!$CD8)), "2nd Extension Funding Out", IF(NOT(ISBLANK('FY2023 MEDEVAC Tracker'!$CC8)), "2nd Extension In Processing", IF(NOT(ISBLANK('FY2023 MEDEVAC Tracker'!$BL8)), "1st Extension Funding Out", IF(NOT(ISBLANK('FY2023 MEDEVAC Tracker'!$BK8)), "1st Extension In Processing", IF(NOT(ISBLANK('FY2023 MEDEVAC Tracker'!$AR8)), "Amendment Funding Out", IF(NOT(ISBLANK('FY2023 MEDEVAC Tracker'!$AQ8)), "Amendment In Processing", IF(NOT(ISBLANK('FY2023 MEDEVAC Tracker'!$X8)), "Initial Funding Out", IF(NOT(ISBLANK('FY2023 MEDEVAC Tracker'!$W8)), "Initial In Processing", IF(NOT(ISBLANK('FY2023 MEDEVAC Tracker'!$W8)), "Initiated", "N/A"))))))))))))))))))))) -> Final Acct | C8: =IF(NOT(ISBLANK('FY2023 MEDEVAC Tracker'!$HP8)), IF(ISBLANK('FY2023 MEDEVAC Tracker'!$HQ8), "N/A", IF(ISBLANK('FY2023 MEDEVAC Tracker'!$HR8), TODAY()-'FY2023 MEDEVAC Tracker'!$HQ8, "Sent")), IF(NOT(ISBLANK('FY2023 MEDEVAC Tracker'!$GX8)), IF(ISBLANK('FY2023 MEDEVAC Tracker'!$GY8), "N/A", IF(ISBLANK('FY2023 MEDEVAC Tracker'!$GZ8), TODAY()-'FY2023 MEDEVAC Tracker'!$GY8, "Sent")), IF(NOT(ISBLANK('FY2023 MEDEVAC Tracker'!$GF8)), IF(ISBLANK('FY2023 MEDEVAC Tracker'!$GG8), "N/A", IF(ISBLANK('FY2023 MEDEVAC Tracker'!$GH8), TODAY()-'FY2023 MEDEVAC Tracker'!$GG8, "Sent")), IF(NOT(ISBLANK('FY2023 MEDEVAC Tracker'!$FN8)), IF(ISBLANK('FY2023 MEDEVAC Tracker'!$FO8), "N/A", IF(ISBLANK('FY2023 MEDEVAC Tracker'!$FP8), TODAY()-'FY2023 MEDEVAC Tracker'!$FO8, "Sent")), IF(NOT(ISBLANK('FY2023 MEDEVAC Tracker'!$EV8)), IF(ISBLANK('FY2023 MEDEVAC Tracker'!$EW8), "N/A", IF(ISBLANK('FY2023 MEDEVAC Tracker'!$EX8), TODAY()-'FY2023 MEDEVAC Tracker'!$EW8, "Sent")), IF(NOT(ISBLANK('FY2023 MEDEVAC Tracker'!$ED8)), IF(ISBLANK('FY2023 MEDEVAC Tracker'!$EE8), "N/A", IF(ISBLANK('FY2023 MEDEVAC Tracker'!$EF8), TODAY()-'FY2023 MEDEVAC Tracker'!$EE8, "Sent")), IF(NOT(ISBLANK('FY2023 MEDEVAC Tracker'!$DL8)), IF(ISBLANK('FY2023 MEDEVAC Tracker'!$DM8), "N/A", IF(ISBLANK('FY2023 MEDEVAC Tracker'!$DN8), TODAY()-'FY2023 MEDEVAC Tracker'!$DM8, "Sent")), IF(NOT(ISBLANK('FY2023 MEDEVAC Tracker'!$CT8)), IF(ISBLANK('FY2023 MEDEVAC Tracker'!$CU8), "N/A", IF(ISBLANK('FY2023 MEDEVAC Tracker'!$CV8), TODAY()-'FY2023 MEDEVAC Tracker'!$CU8, "Sent")),IF(NOT(ISBLANK('FY2023 MEDEVAC Tracker'!$CB8)), IF(ISBLANK('FY2023 MEDEVAC Tracker'!$CC8), "N/A", IF(ISBLANK('FY2023 MEDEVAC Tracker'!$CD8), TODAY()-'FY2023 MEDEVAC Tracker'!$CC8, "Sent")),IF(NOT(ISBLANK('FY2023 MEDEVAC Tracker'!$BJ8)), IF(ISBLANK('FY2023 MEDEVAC Tracker'!$BK8), "N/A", IF(ISBLANK('FY2023 MEDEVAC Tracker'!$BL8), TODAY()-'FY2023 MEDEVAC Tracker'!$BK8, "Sent")), IF(NOT(ISBLANK('FY2023 MEDEVAC Tracker'!$AP8)), IF(ISBLANK('FY2023 MEDEVAC Tracker'!$AQ8), "N/A", IF(ISBLANK('FY2023 MEDEVAC Tracker'!$AR8), TODAY()-'FY2023 MEDEVAC Tracker'!$AQ8, "Sent")), IF(NOT(ISBLANK('FY2023 MEDEVAC Tracker'!$I8)), IF(ISBLANK('FY2023 MEDEVAC Tracker'!$W8), "N/A", IF(ISBLANK('FY2023 MEDEVAC Tracker'!$X8), TODAY()-'FY2023 MEDEVAC Tracker'!$W8, "Sent")),"N/A")))))))))))) -> N/A | D8: =_xlfn.NUMBERVALUE(CONCATENATE(RIGHT(YEAR((TODAY()-860)), 3), IF(OR('FY2023 MEDEVAC Tracker'!$E8="DOS", 'FY2023 MEDEVAC Tracker'!$E8="Seabee", 'FY2023 MEDEVAC Tracker'!$E8="DOS/Seabee"),10, 90), TEXT(((COUNTIF($E$8:E8, E8))-1),"000"))) -> 2310000 | E8: DOS | F8: Vinson Sack | G8: =IF(ISBLANK('FY2023 MEDEVAC Tracker'!$AO8), 'FY2023 MEDEVAC Tracker'!$AN8, 'FY2023 MEDEVAC Tracker'!$BI8)+'FY2023 MEDEVAC Tracker'!$CA8+'FY2023 MEDEVAC Tracker'!$CS8+'FY2023 MEDEVAC Tracker'!$DK8+'FY2023 MEDEVAC Tracker'!$EC8+'FY2023 MEDEVAC Tracker'!$EU8+'FY2023 MEDEVAC Tracker'!$FM8+'FY2023 MEDEVAC Tracker'!$GE8+'FY2023 MEDEVAC Tracker'!$GW8+'FY2023 MEDEVAC Tracker'!$HO8+'FY2023 MEDEVAC Tracker'!$IG8 -> #REF! | H8: =IF(ISBLANK('FY2023 MEDEVAC Tracker'!$AO8), 'FY2023 MEDEVAC Tracker'!$S8, 'FY2023 MEDEVAC Tracker'!$AO8) -> 44851 | I8: =MAX('FY2023 MEDEVAC Tracker'!$T8, 'FY2023 MEDEVAC Tracker'!$AP8, 'FY2023 MEDEVAC Tracker'!$BJ8, 'FY2023 MEDEVAC Tracker'!$CB8, 'FY2023 MEDEVAC Tracker'!$CT8, 'FY2023 MEDEVAC Tracker'!$DL8, 'FY2023 MEDEVAC Tracker'!$ED8, 'FY2023 MEDEVAC Tracker'!$EV8, 'FY2023 MEDEVAC Tracker'!$FN8, 'FY2023 MEDEVAC Tracker'!$GF8, 'FY2023 MEDEVAC Tracker'!$GX8, 'FY2023 MEDEVAC Tracker'!$HP8, ) -> 44857 | J8: MEDICAL | K8: EMP | L8: EMP | M8: =VLOOKUP('FY2023 MEDEVAC Tracker'!$N8, List!F:H, 3, FALSE) -> EUR | N8: WARSAW | O8: =IF(NOT(ISBLANK('FY2023 MEDEVAC Tracker'!$HU8)), 'FY2023 MEDEVAC Tracker'!$HU8, IF(NOT(ISBLANK('FY2023 MEDEVAC Tracker'!$HC8)), 'FY2023 MEDEVAC Tracker'!$HC8, IF(NOT(ISBLANK('FY2023 MEDEVAC Tracker'!$GK8)), 'FY2023 MEDEVAC Tracker'!$GK8, IF(NOT(ISBLANK('FY2023 MEDEVAC Tracker'!$FS8)), 'FY2023 MEDEVAC Tracker'!$FS8, IF(NOT(ISBLANK('FY2023 MEDEVAC Tracker'!$FA8)), 'FY2023 MEDEVAC Tracker'!$FA8, IF(NOT(ISBLANK('FY2023 MEDEVAC Tracker'!$EI8)), 'FY2023 MEDEVAC Tracker'!$EI8, IF(NOT(ISBLANK('FY2023 MEDEVAC Tracker'!$DQ8)), 'FY2023 MEDEVAC Tracker'!$DQ8, IF(NOT(ISBLANK('FY2023 MEDEVAC Tracker'!$CY8)), 'FY2023 MEDEVAC Tracker'!$CY8, IF(NOT(ISBLANK('FY2023 MEDEVAC Tracker'!$CG8)), 'FY2023 MEDEVAC Tracker'!$CG8, IF(NOT(ISBLANK('FY2023 MEDEVAC Tracker'!$BO8)), 'FY2023 MEDEVAC Tracker'!$BO8, IF(NOT(ISBLANK('FY2023 MEDEVAC Tracker'!$AU8)), 'FY2023 MEDEVAC Tracker'!$AU8, IF(NOT(ISBLANK('FY2023 MEDEVAC Tracker'!$V8)), 'FY2023 MEDEVAC Tracker'!$V8, 'FY2023 MEDEVAC Tracker'!$V8)))))))))))) -> LONDON | P8: OCONUS | Q8: =IF(NOT(ISBLANK('FY2023 MEDEVAC Tracker'!#REF!)), 10, IF(NOT(ISBLANK('FY2023 MEDEVAC Tracker'!#REF!)), 9, IF(NOT(ISBLANK('FY2023 MEDEVAC Tracker'!#REF!)), 8, IF(NOT(ISBLANK('FY2023 MEDEVAC Tracker'!#REF!)), 7, IF(NOT(ISBLANK('FY2023 MEDEVAC Tracker'!#REF!)), 6, IF(NOT(ISBLANK('FY2023 MEDEVAC Tracker'!#REF!)), 5, IF(NOT(ISBLANK('FY2023 MEDEVAC Tracker'!#REF!)), 4, IF(NOT(ISBLANK('FY2023 MEDEVAC Tracker'!#REF!)), 3, IF(NOT(ISBLANK('FY2023 MEDEVAC Tracker'!#REF!)), 2, IF(NOT(ISBLANK('FY2023 MEDEVAC Tracker'!#REF!)), 1, 0)))))))))) -> 10 | R8: =IF(IF(NOT(ISBLANK('FY2023 MEDEVAC Tracker'!$ED8)), 'FY2023 MEDEVAC Tracker'!$ED8-'FY2023 MEDEVAC Tracker'!#REF!, IF(NOT(ISBLANK('FY2023 MEDEVAC Tracker'!$DL8)), 'FY2023 MEDEVAC Tracker'!$DL8-'FY2023 MEDEVAC Tracker'!#REF!, IF(NOT(ISBLANK('FY2023 MEDEVAC Tracker'!$CT8)), 'FY2023 MEDEVAC Tracker'!$CT8-'FY2023 MEDEVAC Tracker'!#REF!, IF(NOT(ISBLANK('FY2023 MEDEVAC Tracker'!$CB8)), 'FY2023 MEDEVAC Tracker'!$CB8-'FY2023 MEDEVAC Tracker'!#REF!, IF(NOT(ISBLANK('FY2023 MEDEVAC Tracker'!$AO8)), 'FY2023 MEDEVAC Tracker'!$AO8-'FY2023 MEDEVAC Tracker'!#REF!, 0)))))<30, "0-30", IF(IF(NOT(ISBLANK('FY2023 MEDEVAC Tracker'!$ED8)), 'FY2023 MEDEVAC Tracker'!$ED8-'FY2023 MEDEVAC Tracker'!#REF!, IF(NOT(ISBLANK('FY2023 MEDEVAC Tracker'!$DL8)), 'FY2023 MEDEVAC Tracker'!$DL8-'FY2023 MEDEVAC Tracker'!#REF!, IF(NOT(ISBLANK('FY2023 MEDEVAC Tracker'!$CT8)), 'FY2023 MEDEVAC Tracker'!$CT8-'FY2023 MEDEVAC Tracker'!#REF!, IF(NOT(ISBLANK('FY2023 MEDEVAC Tracker'!$CB8)), 'FY2023 MEDEVAC Tracker'!$CB8-'FY2023 MEDEVAC Tracker'!#REF!, IF(NOT(ISBLANK('FY2023 MEDEVAC Tracker'!$AO8)), 'FY2023 MEDEVAC Tracker'!$AO8-'FY2023 MEDEVAC Tracker'!#REF!, 0)))))<60, "31-60", IF(IF(NOT(ISBLANK('FY2023 MEDEVAC Tracker'!$ED8)), 'FY2023 MEDEVAC Tracker'!$ED8-'FY2023 MEDEVAC Tracker'!#REF!, IF(NOT(ISBLANK('FY2023 MEDEVAC Tracker'!$DL8)), 'FY2023 MEDEVAC Tracker'!$DL8-'FY2023 MEDEVAC Tracker'!#REF!, IF(NOT(ISBLANK('FY2023 MEDEVAC Tracker'!$CT8)), 'FY2023 MEDEVAC Tracker'!$CT8-'FY2023 MEDEVAC Tracker'!#REF!, IF(NOT(ISBLANK('FY2023 MEDEVAC Tracker'!$CB8)), 'FY2023 MEDEVAC Tracker'!$CB8-'FY2023 MEDEVAC Tracker'!#REF!, IF(NOT(ISBLANK('FY2023 MEDEVAC Tracker'!$AO8)), 'FY2023 MEDEVAC Tracker'!$AO8-'FY2023 MEDEVAC Tracker'!#REF!, 0)))))<=90, "61-90", IF(IF(NOT(ISBLANK('FY2023 MEDEVAC Tracker'!$ED8)), 'FY2023 MEDEVAC Tracker'!$ED8-'FY2023 MEDEVAC Tracker'!#REF!, IF(NOT(ISBLANK('FY2023 MEDEVAC Tracker'!$DL8)), 'FY2023 MEDEVAC Tracker'!$DL8-'FY2023 MEDEVAC Tracker'!#REF!, IF(NOT(ISBLANK('FY2023 MEDEVAC Tracker'!$CT8)), 'FY2023 MEDEVAC Tracker'!$CT8-'FY2023 MEDEVAC Tracker'!#REF!, IF(NOT(ISBLANK('FY2023 MEDEVAC Tracker'!$CB8)), 'FY2023 MEDEVAC Tracker'!$CB8-'FY2023 MEDEVAC Tracker'!#REF!, IF(NOT(ISBLANK('FY2023 MEDEVAC Tracker'!$AO8)), 'FY2023 MEDEVAC Tracker'!$AO8-'FY2023 MEDEVAC Tracker'!#REF!, 0)))))>90, "91+", "N/A")))) -> 0-30 | S8: 44851 | T8: 44857 | U8: =_xlfn.DAYS('FY2023 MEDEVAC Tracker'!$T8,'FY2023 MEDEVAC Tracker'!$S8)+1 -> 7 | V8: LONDON | W8: 44837 | X8: 44851 | Y8: FS | Z8: =IF(OR(ISBLANK('FY2023 MEDEVAC Tracker'!$W8), ISBLANK('FY2023 MEDEVAC Tracker'!$X8)), "N/A", (NETWORKDAYS('FY2023 MEDEVAC Tracker'!$W8,'FY2023 MEDEVAC Tracker'!$X8)+1)) -> 12 | AA8: 439 | AB8: 7 | AI8: 1000 | AJ8: =('FY2023 MEDEVAC Tracker'!$AA8*[1]AH11Tracker!$AB8)+('FY2023 MEDEVAC Tracker'!$AC8*'FY2023 MEDEVAC Tracker'!$AD8)+('FY2023 MEDEVAC Tracker'!$AE8*'FY2023 MEDEVAC Tracker'!$AF8)+('FY2023 MEDEVAC Tracker'!$AG8*'FY2023 MEDEVAC Tracker'!$AH8) -> #REF! | AK8: 0 | AL8: 300 | AM8: ='FY2023 MEDEVAC Tracker'!$AJ8+'FY2023 MEDEVAC Tracker'!$AK8+'FY2023 MEDEVAC Tracker'!$AL8 -> #REF! | AN8: =AI8+AM8 -> #REF! | AP8: 44854 | AT8: =IF(OR(ISBLANK('FY2023 MEDEVAC Tracker'!$AQ8), ISBLANK('FY2023 MEDEVAC Tracker'!$AR8)), "N/A",'FY2023 MEDEVAC Tracker'!$AR8-'FY2023 MEDEVAC Tracker'!$AQ8) -> N/A | BE8: 0 | BG8: =IF(ISBLANK('FY2023 MEDEVAC Tracker'!$BD8), 0, BD8-'FY2023 MEDEVAC Tracker'!$AI8) -> 0 | BH8: =MAX(0,IF(ISBLANK(AO8), 0, (((AV8*AW8)+(AX8*AY8)+(AZ8*BA8)+(BB8*BC8)+BE8+BF8)-AM8))) -> 0 | BI8: =IF(ISBLANK('FY2023 MEDEVAC Tracker'!$AO8), 0, SUM(AN8,BG8,BH8)) -> 0 | BN8: =IF(OR(ISBLANK('FY2023 MEDEVAC Tracker'!$BK8), ISBLANK('FY2023 MEDEVAC Tracker'!$BL8)), "N/A",'FY2023 MEDEVAC Tracker'!$BL8-'FY2023 MEDEVAC Tracker'!$BK8) -> N/A | BY8: 0 | BZ8: =((BP8*BQ8)+(BR8*BS8)+(BT8*BU8)+(BV8*BW8))+BY8 -> 0 | CA8: =BZ8+BX8 -> 0 | CF8: =IF(OR(ISBLANK('FY2023 MEDEVAC Tracker'!$CC8), ISBLANK('FY2023 MEDEVAC Tracker'!$CD8)), "N/A",'FY2023 MEDEVAC Tracker'!$CD8-'FY2023 MEDEVAC Tracker'!$CC8) -> N/A | CQ8: 0 | CR8: =((CH8*CI8)+(CJ8*CK8)+(CL8*CM8)+(CN8*CO8))+CQ8 -> 0 | CS8: =CR8+CP8 -> 0 | CX8: =IF(OR(ISBLANK('FY2023 MEDEVAC Tracker'!$CU8), ISBLANK('FY2023 MEDEVAC Tracker'!$CV8)), "N/A",'FY2023 MEDEVAC Tracker'!$CV8-'FY2023 MEDEVAC Tracker'!$CU8) -> N/A | DI8: 0 | DJ8: =((CZ8*DA8)+(DB8*DC8)+(DD8*DE8)+(DF8*DG8))+DI8 -> 0 | DK8: =DJ8+DH8 -> 0 | DP8: =IF(OR(ISBLANK('FY2023 MEDEVAC Tracker'!$DM8), ISBLANK('FY2023 MEDEVAC Tracker'!$DN8)), "N/A",'FY2023 MEDEVAC Tracker'!$DN8-'FY2023 MEDEVAC Tracker'!$DM8) -> N/A | EA8: 0 | EB8: =((DR8*DS8)+(DT8*DU8)+(DV8*DW8)+(DX8*DY8))+EA8 -> 0 | EC8: =EB8+DZ8 -> 0 | EH8: =IF(OR(ISBLANK('FY2023 MEDEVAC Tracker'!$EE8), ISBLANK('FY2023 MEDEVAC Tracker'!$EF8)), "N/A",'FY2023 MEDEVAC Tracker'!$EF8-'FY2023 MEDEVAC Tracker'!$EE8) -> N/A | ES8: 0 | ET8: =((EJ8*EK8)+(EL8*EM8)+(EN8*EO8)+(EP8*EQ8))+ES8 -> 0 | EU8: =ET8+ER8 -> 0 | EZ8: =IF(OR(ISBLANK('FY2023 MEDEVAC Tracker'!$EE8), ISBLANK('FY2023 MEDEVAC Tracker'!$EF8)), "N/A",'FY2023 MEDEVAC Tracker'!$EF8-'FY2023 MEDEVAC Tracker'!$EE8) -> N/A | FK8: 0 | FL8: =((FT8*FU8)+(FV8*FW8)+(FF8*FG8)+(FH8*FI8))+FK8 -> 0 | FM8: =FL8+FJ8 -> 0 | FR8: =IF(OR(ISBLANK('FY2023 MEDEVAC Tracker'!$EE8), ISBLANK('FY2023 MEDEVAC Tracker'!$EF8)), "N/A",'FY2023 MEDEVAC Tracker'!$EF8-'FY2023 MEDEVAC Tracker'!$EE8) -> N/A | GC8: 0 | GD8: 0 | GE8: =GD8+GB8 -> 0 | GJ8: =IF(OR(ISBLANK('FY2023 MEDEVAC Tracker'!$GH8), ISBLANK('FY2023 MEDEVAC Tracker'!$GG8)), "N/A",'FY2023 MEDEVAC Tracker'!$GG8-'FY2023 MEDEVAC Tracker'!$GH8) -> N/A | GU8: 0 | GV8: =((GL8*GM8)+(GN8*GO8)+(GP8*GQ8)+(GR8*GS8))+GU8 -> 0 | GW8: =GV8+GT8 -> 0 | HB8: =IF(OR(ISBLANK('FY2023 MEDEVAC Tracker'!$GY8), ISBLANK('FY2023 MEDEVAC Tracker'!$GZ8)), "N/A",'FY2023 MEDEVAC Tracker'!#REF!-'FY2023 MEDEVAC Tracker'!#REF!) -> N/A | HM8: 0 | HN8: 0 | HO8: 0 | HT8: N/A | IE8: 0 | IF8: 0 | IG8: 0 | IH8: Final Acct | II8: 44896 | IJ8: =IF(ISBLANK('FY2023 MEDEVAC Tracker'!$AO8), 'FY2023 MEDEVAC Tracker'!$H8, 'FY2023 MEDEVAC Tracker'!$AO8) -> 44851 | IK8: =MAX('FY2023 MEDEVAC Tracker'!$HP8, 'FY2023 MEDEVAC Tracker'!$GX8, 'FY2023 MEDEVAC Tracker'!$GF8, 'FY2023 MEDEVAC Tracker'!$FN8, 'FY2023 MEDEVAC Tracker'!$EV8, 'FY2023 MEDEVAC Tracker'!$ED8, 'FY2023 MEDEVAC Tracker'!$DL8, 'FY2023 MEDEVAC Tracker'!$CT8, 'FY2023 MEDEVAC Tracker'!$CB8, 'FY2023 MEDEVAC Tracker'!$BJ8, 'FY2023 MEDEVAC Tracker'!$AP8, 'FY2023 MEDEVAC Tracker'!$I8) -> 44857 | IL8: 1034.69 | IM8: 1471.77 | IN8: =IM8+IL8 -> 2506.46 | IO8: =G8-IN8 -> #REF! | IQ8: 44887
B9: =IF(NOT(ISBLANK('FY2023 MEDEVAC Tracker'!$IH9)), IH9, IF(NOT(ISBLANK('FY2023 MEDEVAC Tracker'!$HR9)), "10th Extension Funding Out", IF(NOT(ISBLANK('FY2023 MEDEVAC Tracker'!$GZ9)), "9th Extension Funding Out", IF(NOT(ISBLANK('FY2023 MEDEVAC Tracker'!$GH9)), "8th Extension Funding Out", IF(NOT(ISBLANK('FY2023 MEDEVAC Tracker'!$FP9)), "7th Extension Funding Out", IF(NOT(ISBLANK('FY2023 MEDEVAC Tracker'!$EX9)), "6th Extension Funding Out", IF(NOT(ISBLANK('FY2023 MEDEVAC Tracker'!$EF9)), "5th Extension Funding Out", IF(NOT(ISBLANK('FY2023 MEDEVAC Tracker'!$EE9)), "5th Extension In Processing", IF(NOT(ISBLANK('FY2023 MEDEVAC Tracker'!$DN9)), "4th Extension Funding Out", IF(NOT(ISBLANK('FY2023 MEDEVAC Tracker'!$DM9)), "4th Extension In Processing",IF(NOT(ISBLANK('FY2023 MEDEVAC Tracker'!$CV9)), "3rd Extension Funding Out", IF(NOT(ISBLANK('FY2023 MEDEVAC Tracker'!$CU9)), "3rd Extension In Processing", IF(NOT(ISBLANK('FY2023 MEDEVAC Tracker'!$CD9)), "2nd Extension Funding Out", IF(NOT(ISBLANK('FY2023 MEDEVAC Tracker'!$CC9)), "2nd Extension In Processing", IF(NOT(ISBLANK('FY2023 MEDEVAC Tracker'!$BL9)), "1st Extension Funding Out", IF(NOT(ISBLANK('FY2023 MEDEVAC Tracker'!$BK9)), "1st Extension In Processing", IF(NOT(ISBLANK('FY2023 MEDEVAC Tracker'!$AR9)), "Amendment Funding Out", IF(NOT(ISBLANK('FY2023 MEDEVAC Tracker'!$AQ9)), "Amendment In Processing", IF(NOT(ISBLANK('FY2023 MEDEVAC Tracker'!$X9)), "Initial Funding Out", IF(NOT(ISBLANK('FY2023 MEDEVAC Tracker'!$W9)), "Initial In Processing", IF(NOT(ISBLANK('FY2023 MEDEVAC Tracker'!$W9)), "Initiated", "N/A"))))))))))))))))))))) -> Terminated | C9: =IF(NOT(ISBLANK('FY2023 MEDEVAC Tracker'!$HP9)), IF(ISBLANK('FY2023 MEDEVAC Tracker'!$HQ9), "N/A", IF(ISBLANK('FY2023 MEDEVAC Tracker'!$HR9), TODAY()-'FY2023 MEDEVAC Tracker'!$HQ9, "Sent")), IF(NOT(ISBLANK('FY2023 MEDEVAC Tracker'!$GX9)), IF(ISBLANK('FY2023 MEDEVAC Tracker'!$GY9), "N/A", IF(ISBLANK('FY2023 MEDEVAC Tracker'!$GZ9), TODAY()-'FY2023 MEDEVAC Tracker'!$GY9, "Sent")), IF(NOT(ISBLANK('FY2023 MEDEVAC Tracker'!$GF9)), IF(ISBLANK('FY2023 MEDEVAC Tracker'!$GG9), "N/A", IF(ISBLANK('FY2023 MEDEVAC Tracker'!$GH9), TODAY()-'FY2023 MEDEVAC Tracker'!$GG9, "Sent")), IF(NOT(ISBLANK('FY2023 MEDEVAC Tracker'!$FN9)), IF(ISBLANK('FY2023 MEDEVAC Tracker'!$FO9), "N/A", IF(ISBLANK('FY2023 MEDEVAC Tracker'!$FP9), TODAY()-'FY2023 MEDEVAC Tracker'!$FO9, "Sent")), IF(NOT(ISBLANK('FY2023 MEDEVAC Tracker'!$EV9)), IF(ISBLANK('FY2023 MEDEVAC Tracker'!$EW9), "N/A", IF(ISBLANK('FY2023 MEDEVAC Tracker'!$EX9), TODAY()-'FY2023 MEDEVAC Tracker'!$EW9, "Sent")), IF(NOT(ISBLANK('FY2023 MEDEVAC Tracker'!$ED9)), IF(ISBLANK('FY2023 MEDEVAC Tracker'!$EE9), "N/A", IF(ISBLANK('FY2023 MEDEVAC Tracker'!$EF9), TODAY()-'FY2023 MEDEVAC Tracker'!$EE9, "Sent")), IF(NOT(ISBLANK('FY2023 MEDEVAC Tracker'!$DL9)), IF(ISBLANK('FY2023 MEDEVAC Tracker'!$DM9), "N/A", IF(ISBLANK('FY2023 MEDEVAC Tracker'!$DN9), TODAY()-'FY2023 MEDEVAC Tracker'!$DM9, "Sent")), IF(NOT(ISBLANK('FY2023 MEDEVAC Tracker'!$CT9)), IF(ISBLANK('FY2023 MEDEVAC Tracker'!$CU9), "N/A", IF(ISBLANK('FY2023 MEDEVAC Tracker'!$CV9), TODAY()-'FY2023 MEDEVAC Tracker'!$CU9, "Sent")),IF(NOT(ISBLANK('FY2023 MEDEVAC Tracker'!$CB9)), IF(ISBLANK('FY2023 MEDEVAC Tracker'!$CC9), "N/A", IF(ISBLANK('FY2023 MEDEVAC Tracker'!$CD9), TODAY()-'FY2023 MEDEVAC Tracker'!$CC9, "Sent")),IF(NOT(ISBLANK('FY2023 MEDEVAC Tracker'!$BJ9)), IF(ISBLANK('FY2023 MEDEVAC Tracker'!$BK9), "N/A", IF(ISBLANK('FY2023 MEDEVAC Tracker'!$BL9), TODAY()-'FY2023 MEDEVAC Tracker'!$BK9, "Sent")), IF(NOT(ISBLANK('FY2023 MEDEVAC Tracker'!$AP9)), IF(ISBLANK('FY2023 MEDEVAC Tracker'!$AQ9), "N/A", IF(ISBLANK('FY2023 MEDEVAC Tracker'!$AR9), TODAY()-'FY2023 MEDEVAC Tracker'!$AQ9, "Sent")), IF(NOT(ISBLANK('FY2023 MEDEVAC Tracker'!$I9)), IF(ISBLANK('FY2023 MEDEVAC Tracker'!$W9), "N/A", IF(ISBLANK('FY2023 MEDEVAC Tracker'!$X9), TODAY()-'FY2023 MEDEVAC Tracker'!$W9, "Sent")),"N/A")))))))))))) -> Sent | D9: =_xlfn.NUMBERVALUE(CONCATENATE(RIGHT(YEAR((TODAY()-860)), 3), IF(OR('FY2023 MEDEVAC Tracker'!$E9="DOS", 'FY2023 MEDEVAC Tracker'!$E9="Seabee", 'FY2023 MEDEVAC Tracker'!$E9="DOS/Seabee"),10, 90), TEXT(((COUNTIF($E$8:E12, E9))-1),"000"))) -> 2390000 | E9: MSG | F9: Mohammad Shams | G9: =IF(ISBLANK('FY2023 MEDEVAC Tracker'!$AO9), 'FY2023 MEDEVAC Tracker'!$AN9, 'FY2023 MEDEVAC Tracker'!$BI9)+'FY2023 MEDEVAC Tracker'!$CA9+'FY2023 MEDEVAC Tracker'!$CS9+'FY2023 MEDEVAC Tracker'!$DK9+'FY2023 MEDEVAC Tracker'!$EC9+'FY2023 MEDEVAC Tracker'!$EU9+'FY2023 MEDEVAC Tracker'!$FM9+'FY2023 MEDEVAC Tracker'!$GE9+'FY2023 MEDEVAC Tracker'!$GW9+'FY2023 MEDEVAC Tracker'!$HO9+'FY2023 MEDEVAC Tracker'!$IG9 -> #REF! | H9: =IF(ISBLANK('FY2023 MEDEVAC Tracker'!$AO9), 'FY2023 MEDEVAC Tracker'!$S9, 'FY2023 MEDEVAC Tracker'!$AO9) -> 44837 | I9: =MAX('FY2023 MEDEVAC Tracker'!$T9, 'FY2023 MEDEVAC Tracker'!$AP9, 'FY2023 MEDEVAC Tracker'!$BJ9, 'FY2023 MEDEVAC Tracker'!$CB9, 'FY2023 MEDEVAC Tracker'!$CT9, 'FY2023 MEDEVAC Tracker'!$DL9, 'FY2023 MEDEVAC Tracker'!$ED9, 'FY2023 MEDEVAC Tracker'!$EV9, 'FY2023 MEDEVAC Tracker'!$FN9, 'FY2023 MEDEVAC Tracker'!$GF9, 'FY2023 MEDEVAC Tracker'!$GX9, 'FY2023 MEDEVAC Tracker'!$HP9, ) -> 44839 | J9: MHS-MSG | K9: EMP | L9: EMP | M9: =VLOOKUP('FY2023 MEDEVAC Tracker'!$N9, List!F:H, 3, FALSE) -> EUR | N9: TALLINN | O9: =IF(NOT(ISBLANK('FY2023 MEDEVAC Tracker'!$HU9)), 'FY2023 MEDEVAC Tracker'!$HU9, IF(NOT(ISBLANK('FY2023 MEDEVAC Tracker'!$HC9)), 'FY2023 MEDEVAC Tracker'!$HC9, IF(NOT(ISBLANK('FY2023 MEDEVAC Tracker'!$GK9)), 'FY2023 MEDEVAC Tracker'!$GK9, IF(NOT(ISBLANK('FY2023 MEDEVAC Tracker'!$FS9)), 'FY2023 MEDEVAC Tracker'!$FS9, IF(NOT(ISBLANK('FY2023 MEDEVAC Tracker'!$FA9)), 'FY2023 MEDEVAC Tracker'!$FA9, IF(NOT(ISBLANK('FY2023 MEDEVAC Tracker'!$EI9)), 'FY2023 MEDEVAC Tracker'!$EI9, IF(NOT(ISBLANK('FY2023 MEDEVAC Tracker'!$DQ9)), 'FY2023 MEDEVAC Tracker'!$DQ9, IF(NOT(ISBLANK('FY2023 MEDEVAC Tracker'!$CY9)), 'FY2023 MEDEVAC Tracker'!$CY9, IF(NOT(ISBLANK('FY2023 MEDEVAC Tracker'!$CG9)), 'FY2023 MEDEVAC Tracker'!$CG9, IF(NOT(ISBLANK('FY2023 MEDEVAC Tracker'!$BO9)), 'FY2023 MEDEVAC Tracker'!$BO9, IF(NOT(ISBLANK('FY2023 MEDEVAC Tracker'!$AU9)), 'FY2023 MEDEVAC Tracker'!$AU9, IF(NOT(ISBLANK('FY2023 MEDEVAC Tracker'!$V9)), 'FY2023 MEDEVAC Tracker'!$V9, 'FY2023 MEDEVAC Tracker'!$V9)))))))))))) -> WASHINGTON, DC | P9: CONUS | Q9: =IF(NOT(ISBLANK('FY2023 MEDEVAC Tracker'!#REF!)), 10, IF(NOT(ISBLANK('FY2023 MEDEVAC Tracker'!#REF!)), 9, IF(NOT(ISBLANK('FY2023 MEDEVAC Tracker'!#REF!)), 8, IF(NOT(ISBLANK('FY2023 MEDEVAC Tracker'!#REF!)), 7, IF(NOT(ISBLANK('FY2023 MEDEVAC Tracker'!#REF!)), 6, IF(NOT(ISBLANK('FY2023 MEDEVAC Tracker'!#REF!)), 5, IF(NOT(ISBLANK('FY2023 MEDEVAC Tracker'!#REF!)), 4, IF(NOT(ISBLANK('FY2023 MEDEVAC Tracker'!#REF!)), 3, IF(NOT(ISBLANK('FY2023 MEDEVAC Tracker'!#REF!)), 2, IF(NOT(ISBLANK('FY2023 MEDEVAC Tracker'!#REF!)), 1, 0)))))))))) -> 10 | R9: =IF(IF(NOT(ISBLANK('FY2023 MEDEVAC Tracker'!$ED9)), 'FY2023 MEDEVAC Tracker'!$ED9-'FY2023 MEDEVAC Tracker'!#REF!, IF(NOT(ISBLANK('FY2023 MEDEVAC Tracker'!$DL9)), 'FY2023 MEDEVAC Tracker'!$DL9-'FY2023 MEDEVAC Tracker'!#REF!, IF(NOT(ISBLANK('FY2023 MEDEVAC Tracker'!$CT9)), 'FY2023 MEDEVAC Tracker'!$CT9-'FY2023 MEDEVAC Tracker'!#REF!, IF(NOT(ISBLANK('FY2023 MEDEVAC Tracker'!$CB9)), 'FY2023 MEDEVAC Tracker'!$CB9-'FY2023 MEDEVAC Tracker'!#REF!, IF(NOT(ISBLANK('FY2023 MEDEVAC Tracker'!$AO9)), 'FY2023 MEDEVAC Tracker'!$AO9-'FY2023 MEDEVAC Tracker'!#REF!, 0)))))<30, "0-30", IF(IF(NOT(ISBLANK('FY2023 MEDEVAC Tracker'!$ED9)), 'FY2023 MEDEVAC Tracker'!$ED9-'FY2023 MEDEVAC Tracker'!#REF!, IF(NOT(ISBLANK('FY2023 MEDEVAC Tracker'!$DL9)), 'FY2023 MEDEVAC Tracker'!$DL9-'FY2023 MEDEVAC Tracker'!#REF!, IF(NOT(ISBLANK('FY2023 MEDEVAC Tracker'!$CT9)), 'FY2023 MEDEVAC Tracker'!$CT9-'FY2023 MEDEVAC Tracker'!#REF!, IF(NOT(ISBLANK('FY2023 MEDEVAC Tracker'!$CB9)), 'FY2023 MEDEVAC Tracker'!$CB9-'FY2023 MEDEVAC Tracker'!#REF!, IF(NOT(ISBLANK('FY2023 MEDEVAC Tracker'!$AO9)), 'FY2023 MEDEVAC Tracker'!$AO9-'FY2023 MEDEVAC Tracker'!#REF!, 0)))))<60, "31-60", IF(IF(NOT(ISBLANK('FY2023 MEDEVAC Tracker'!$ED9)), 'FY2023 MEDEVAC Tracker'!$ED9-'FY2023 MEDEVAC Tracker'!#REF!, IF(NOT(ISBLANK('FY2023 MEDEVAC Tracker'!$DL9)), 'FY2023 MEDEVAC Tracker'!$DL9-'FY2023 MEDEVAC Tracker'!#REF!, IF(NOT(ISBLANK('FY2023 MEDEVAC Tracker'!$CT9)), 'FY2023 MEDEVAC Tracker'!$CT9-'FY2023 MEDEVAC Tracker'!#REF!, IF(NOT(ISBLANK('FY2023 MEDEVAC Tracker'!$CB9)), 'FY2023 MEDEVAC Tracker'!$CB9-'FY2023 MEDEVAC Tracker'!#REF!, IF(NOT(ISBLANK('FY2023 MEDEVAC Tracker'!$AO9)), 'FY2023 MEDEVAC Tracker'!$AO9-'FY2023 MEDEVAC Tracker'!#REF!, 0)))))<=90, "61-90", IF(IF(NOT(ISBLANK('FY2023 MEDEVAC Tracker'!$ED9)), 'FY2023 MEDEVAC Tracker'!$ED9-'FY2023 MEDEVAC Tracker'!#REF!, IF(NOT(ISBLANK('FY2023 MEDEVAC Tracker'!$DL9)), 'FY2023 MEDEVAC Tracker'!$DL9-'FY2023 MEDEVAC Tracker'!#REF!, IF(NOT(ISBLANK('FY2023 MEDEVAC Tracker'!$CT9)), 'FY2023 MEDEVAC Tracker'!$CT9-'FY2023 MEDEVAC Tracker'!#REF!, IF(NOT(ISBLANK('FY2023 MEDEVAC Tracker'!$CB9)), 'FY2023 MEDEVAC Tracker'!$CB9-'FY2023 MEDEVAC Tracker'!#REF!, IF(NOT(ISBLANK('FY2023 MEDEVAC Tracker'!$AO9)), 'FY2023 MEDEVAC Tracker'!$AO9-'FY2023 MEDEVAC Tracker'!#REF!, 0)))))>90, "91+", "N/A")))) -> 0-30 | S9: 44837 | T9: 44839 | U9: =_xlfn.DAYS('FY2023 MEDEVAC Tracker'!$T9,'FY2023 MEDEVAC Tracker'!$S9)+1 -> 3 | V9: WASHINGTON, DC | W9: 44837 | X9: 44851 | Y9: FS | Z9: =IF(OR(ISBLANK('FY2023 MEDEVAC Tracker'!$W9), ISBLANK('FY2023 MEDEVAC Tracker'!$X9)), "N/A", (NETWORKDAYS('FY2023 MEDEVAC Tracker'!$W9,'FY2023 MEDEVAC Tracker'!$X9)+1)) -> 12 | AA9: 336 | AB9: 3 | AI9: 6000 | AJ9: =('FY2023 MEDEVAC Tracker'!$AA9*[1]AH11Tracker!$AB9)+('FY2023 MEDEVAC Tracker'!$AC9*'FY2023 MEDEVAC Tracker'!$AD9)+('FY2023 MEDEVAC Tracker'!$AE9*'FY2023 MEDEVAC Tracker'!$AF9)+('FY2023 MEDEVAC Tracker'!$AG9*'FY2023 MEDEVAC Tracker'!$AH9) -> #REF! | AK9: 1008 | AL9: 200 | AM9: ='FY2023 MEDEVAC Tracker'!$AJ9+'FY2023 MEDEVAC Tracker'!$AK9+'FY2023 MEDEVAC Tracker'!$AL9 -> #REF! | AN9: =AI9+AM9 -> #REF! | AT9: =IF(OR(ISBLANK('FY2023 MEDEVAC Tracker'!$AQ9), ISBLANK('FY2023 MEDEVAC Tracker'!$AR9)), "N/A",'FY2023 MEDEVAC Tracker'!$AR9-'FY2023 MEDEVAC Tracker'!$AQ9) -> N/A | BE9: 0 | BG9: =IF(ISBLANK('FY2023 MEDEVAC Tracker'!$BD9), 0, BD9-'FY2023 MEDEVAC Tracker'!$AI9) -> 0 | BH9: =MAX(0,IF(ISBLANK(AO9), 0, (((AV9*AW9)+(AX9*AY9)+(AZ9*BA9)+(BB9*BC9)+BE9+BF9)-AM9))) -> 0 | BI9: =IF(ISBLANK('FY2023 MEDEVAC Tracker'!$AO9), 0, SUM(AN9,BG9,BH9)) -> 0 | BN9: =IF(OR(ISBLANK('FY2023 MEDEVAC Tracker'!$BK9), ISBLANK('FY2023 MEDEVAC Tracker'!$BL9)), "N/A",'FY2023 MEDEVAC Tracker'!$BL9-'FY2023 MEDEVAC Tracker'!$BK9) -> N/A | BY9: 0 | BZ9: =((BP9*BQ9)+(BR9*BS9)+(BT9*BU9)+(BV9*BW9))+BY9 -> 0 | CA9: =BZ9+BX9 -> 0 | CF9: =IF(OR(ISBLANK('FY2023 MEDEVAC Tracker'!$CC9), ISBLANK('FY2023 MEDEVAC Tracker'!$CD9)), "N/A",'FY2023 MEDEVAC Tracker'!$CD9-'FY2023 MEDEVAC Tracker'!$CC9) -> N/A | CQ9: 0 | CR9: =((CH9*CI9)+(CJ9*CK9)+(CL9*CM9)+(CN9*CO9))+CQ9 -> 0 | CS9: =CR9+CP9 -> 0 | CX9: =IF(OR(ISBLANK('FY2023 MEDEVAC Tracker'!$CU9), ISBLANK('FY2023 MEDEVAC Tracker'!$CV9)), "N/A",'FY2023 MEDEVAC Tracker'!$CV9-'FY2023 MEDEVAC Tracker'!$CU9) -> N/A | DI9: 0 | DJ9: =((CZ9*DA9)+(DB9*DC9)+(DD9*DE9)+(DF9*DG9))+DI9 -> 0 | DK9: =DJ9+DH9 -> 0 | DP9: =IF(OR(ISBLANK('FY2023 MEDEVAC Tracker'!$DM9), ISBLANK('FY2023 MEDEVAC Tracker'!$DN9)), "N/A",'FY2023 MEDEVAC Tracker'!$DN9-'FY2023 MEDEVAC Tracker'!$DM9) -> N/A | EA9: 0 | EB9: =((DR9*DS9)+(DT9*DU9)+(DV9*DW9)+(DX9*DY9))+EA9 -> 0 | EC9: =EB9+DZ9 -> 0 | EH9: =IF(OR(ISBLANK('FY2023 MEDEVAC Tracker'!$EE9), ISBLANK('FY2023 MEDEVAC Tracker'!$EF9)), "N/A",'FY2023 MEDEVAC Tracker'!$EF9-'FY2023 MEDEVAC Tracker'!$EE9) -> N/A | ES9: 0 | ET9: =((EJ9*EK9)+(EL9*EM9)+(EN9*EO9)+(EP9*EQ9))+ES9 -> 0 | EU9: =ET9+ER9 -> 0 | EZ9: =IF(OR(ISBLANK('FY2023 MEDEVAC Tracker'!$EE9), ISBLANK('FY2023 MEDEVAC Tracker'!$EF9)), "N/A",'FY2023 MEDEVAC Tracker'!$EF9-'FY2023 MEDEVAC Tracker'!$EE9) -> N/A | FK9: 0 | FL9: =((FT9*FU9)+(FV9*FW9)+(FF9*FG9)+(FH9*FI9))+FK9 -> 0 | FM9: =FL9+FJ9 -> 0 | FR9: =IF(OR(ISBLANK('FY2023 MEDEVAC Tracker'!$EE9), ISBLANK('FY2023 MEDEVAC Tracker'!$EF9)), "N/A",'FY2023 MEDEVAC Tracker'!$EF9-'FY2023 MEDEVAC Tracker'!$EE9) -> N/A | GC9: 0 | GD9: 0 | GE9: =GD9+GB9 -> 0 | GJ9: =IF(OR(ISBLANK('FY2023 MEDEVAC Tracker'!$GH9), ISBLANK('FY2023 MEDEVAC Tracker'!$GG9)), "N/A",'FY2023 MEDEVAC Tracker'!$GG9-'FY2023 MEDEVAC Tracker'!$GH9) -> N/A | GU9: 0 | GV9: =((GL9*GM9)+(GN9*GO9)+(GP9*GQ9)+(GR9*GS9))+GU9 -> 0 | GW9: =GV9+GT9 -> 0 | HB9: =IF(OR(ISBLANK('FY2023 MEDEVAC Tracker'!$GY9), ISBLANK('FY2023 MEDEVAC Tracker'!$GZ9)), "N/A",'FY2023 MEDEVAC Tracker'!#REF!-'FY2023 MEDEVAC Tracker'!#REF!) -> N/A | HM9: 0 | HN9: 0 | HO9: 0 | IE9: 0 | IF9: 0 | IG9: 0 | IH9: Terminated | IJ9: =IF(ISBLANK('FY2023 MEDEVAC Tracker'!$AO9), 'FY2023 MEDEVAC Tracker'!$H9, 'FY2023 MEDEVAC Tracker'!$AO9) -> 44837 | IK9: =MAX('FY2023 MEDEVAC Tracker'!$HP9, 'FY2023 MEDEVAC Tracker'!$GX9, 'FY2023 MEDEVAC Tracker'!$GF9, 'FY2023 MEDEVAC Tracker'!$FN9, 'FY2023 MEDEVAC Tracker'!$EV9, 'FY2023 MEDEVAC Tracker'!$ED9, 'FY2023 MEDEVAC Tracker'!$DL9, 'FY2023 MEDEVAC Tracker'!$CT9, 'FY2023 MEDEVAC Tracker'!$CB9, 'FY2023 MEDEVAC Tracker'!$BJ9, 'FY2023 MEDEVAC Tracker'!$AP9, 'FY2023 MEDEVAC Tracker'!$I9) -> 44839 | IN9: =IM9+IL9 -> 0 | IO9: =G9-IN9 -> #REF! | IP9: Termination 22 STATE 126468. NMA airfare +3 days authorized. | IQ9: 44869
B10: =IF(NOT(ISBLANK('FY2023 MEDEVAC Tracker'!$IH10)), IH10, IF(NOT(ISBLANK('FY2023 MEDEVAC Tracker'!$HR10)), "10th Extension Funding Out", IF(NOT(ISBLANK('FY2023 MEDEVAC Tracker'!$GZ10)), "9th Extension Funding Out", IF(NOT(ISBLANK('FY2023 MEDEVAC Tracker'!$GH10)), "8th Extension Funding Out", IF(NOT(ISBLANK('FY2023 MEDEVAC Tracker'!$FP10)), "7th Extension Funding Out", IF(NOT(ISBLANK('FY2023 MEDEVAC Tracker'!$EX10)), "6th Extension Funding Out", IF(NOT(ISBLANK('FY2023 MEDEVAC Tracker'!$EF10)), "5th Extension Funding Out", IF(NOT(ISBLANK('FY2023 MEDEVAC Tracker'!$EE10)), "5th Extension In Processing", IF(NOT(ISBLANK('FY2023 MEDEVAC Tracker'!$DN10)), "4th Extension Funding Out", IF(NOT(ISBLANK('FY2023 MEDEVAC Tracker'!$DM10)), "4th Extension In Processing",IF(NOT(ISBLANK('FY2023 MEDEVAC Tracker'!$CV10)), "3rd Extension Funding Out", IF(NOT(ISBLANK('FY2023 MEDEVAC Tracker'!$CU10)), "3rd Extension In Processing", IF(NOT(ISBLANK('FY2023 MEDEVAC Tracker'!$CD10)), "2nd Extension Funding Out", IF(NOT(ISBLANK('FY2023 MEDEVAC Tracker'!$CC10)), "2nd Extension In Processing", IF(NOT(ISBLANK('FY2023 MEDEVAC Tracker'!$BL10)), "1st Extension Funding Out", IF(NOT(ISBLANK('FY2023 MEDEVAC Tracker'!$BK10)), "1st Extension In Processing", IF(NOT(ISBLANK('FY2023 MEDEVAC Tracker'!$AR10)), "Amendment Funding Out", IF(NOT(ISBLANK('FY2023 MEDEVAC Tracker'!$AQ10)), "Amendment In Processing", IF(NOT(ISBLANK('FY2023 MEDEVAC Tracker'!$X10)), "Initial Funding Out", IF(NOT(ISBLANK('FY2023 MEDEVAC Tracker'!$W10)), "Initial In Processing", IF(NOT(ISBLANK('FY2023 MEDEVAC Tracker'!$W10)), "Initiated", "N/A"))))))))))))))))))))) -> N/A | D10: =_xlfn.NUMBERVALUE(CONCATENATE(RIGHT(YEAR((TODAY()-860)), 3), IF(OR('FY2023 MEDEVAC Tracker'!$E10="DOS", 'FY2023 MEDEVAC Tracker'!$E10="Seabee", 'FY2023 MEDEVAC Tracker'!$E10="DOS/Seabee"),10, 90), TEXT(((COUNTIF($E$8:E10, E10))-1),"000"))) -> #VALUE! | G10: =IF(ISBLANK('FY2023 MEDEVAC Tracker'!$AO10), 'FY2023 MEDEVAC Tracker'!$AN10, 'FY2023 MEDEVAC Tracker'!$BI10)+'FY2023 MEDEVAC Tracker'!$CA10+'FY2023 MEDEVAC Tracker'!$CS10+'FY2023 MEDEVAC Tracker'!$DK10+'FY2023 MEDEVAC Tracker'!$EC10+'FY2023 MEDEVAC Tracker'!$EU10+'FY2023 MEDEVAC Tracker'!$FM10+'FY2023 MEDEVAC Tracker'!$GE10+'FY2023 MEDEVAC Tracker'!$GW10+'FY2023 MEDEVAC Tracker'!$HO10+'FY2023 MEDEVAC Tracker'!$IG10 -> #REF! | H10: =IF(ISBLANK('FY2023 MEDEVAC Tracker'!$AO10), 'FY2023 MEDEVAC Tracker'!$S10, 'FY2023 MEDEVAC Tracker'!$AO10) -> 0 | I10: =MAX('FY2023 MEDEVAC Tracker'!$T10, 'FY2023 MEDEVAC Tracker'!$AP10, 'FY2023 MEDEVAC Tracker'!$BJ10, 'FY2023 MEDEVAC Tracker'!$CB10, 'FY2023 MEDEVAC Tracker'!$CT10, 'FY2023 MEDEVAC Tracker'!$DL10, 'FY2023 MEDEVAC Tracker'!$ED10, 'FY2023 MEDEVAC Tracker'!$EV10, 'FY2023 MEDEVAC Tracker'!$FN10, 'FY2023 MEDEVAC Tracker'!$GF10, 'FY2023 MEDEVAC Tracker'!$GX10, 'FY2023 MEDEVAC Tracker'!$HP10, ) -> 0 | M10: =VLOOKUP('FY2023 MEDEVAC Tracker'!$N10, List!F:H, 3, FALSE) -> #N/A | O10: =IF(NOT(ISBLANK('FY2023 MEDEVAC Tracker'!$HU10)), 'FY2023 MEDEVAC Tracker'!$HU10, IF(NOT(ISBLANK('FY2023 MEDEVAC Tracker'!$HC10)), 'FY2023 MEDEVAC Tracker'!$HC10, IF(NOT(ISBLANK('FY2023 MEDEVAC Tracker'!$GK10)), 'FY2023 MEDEVAC Tracker'!$GK10, IF(NOT(ISBLANK('FY2023 MEDEVAC Tracker'!$FS10)), 'FY2023 MEDEVAC Tracker'!$FS10, IF(NOT(ISBLANK('FY2023 MEDEVAC Tracker'!$FA10)), 'FY2023 MEDEVAC Tracker'!$FA10, IF(NOT(ISBLANK('FY2023 MEDEVAC Tracker'!$EI10)), 'FY2023 MEDEVAC Tracker'!$EI10, IF(NOT(ISBLANK('FY2023 MEDEVAC Tracker'!$DQ10)), 'FY2023 MEDEVAC Tracker'!$DQ10, IF(NOT(ISBLANK('FY2023 MEDEVAC Tracker'!$CY10)), 'FY2023 MEDEVAC Tracker'!$CY10, IF(NOT(ISBLANK('FY2023 MEDEVAC Tracker'!$CG10)), 'FY2023 MEDEVAC Tracker'!$CG10, IF(NOT(ISBLANK('FY2023 MEDEVAC Tracker'!$BO10)), 'FY2023 MEDEVAC Tracker'!$BO10, IF(NOT(ISBLANK('FY2023 MEDEVAC Tracker'!$AU10)), 'FY2023 MEDEVAC Tracker'!$AU10, IF(NOT(ISBLANK('FY2023 MEDEVAC Tracker'!$V10)), 'FY2023 MEDEVAC Tracker'!$V10, 'FY2023 MEDEVAC Tracker'!$V10)))))))))))) -> 0 | Q10: =IF(NOT(ISBLANK('FY2023 MEDEVAC Tracker'!#REF!)), 10, IF(NOT(ISBLANK('FY2023 MEDEVAC Tracker'!#REF!)), 9, IF(NOT(ISBLANK('FY2023 MEDEVAC Tracker'!#REF!)), 8, IF(NOT(ISBLANK('FY2023 MEDEVAC Tracker'!#REF!)), 7, IF(NOT(ISBLANK('FY2023 MEDEVAC Tracker'!#REF!)), 6, IF(NOT(ISBLANK('FY2023 MEDEVAC Tracker'!#REF!)), 5, IF(NOT(ISBLANK('FY2023 MEDEVAC Tracker'!#REF!)), 4, IF(NOT(ISBLANK('FY2023 MEDEVAC Tracker'!#REF!)), 3, IF(NOT(ISBLANK('FY2023 MEDEVAC Tracker'!#REF!)), 2, IF(NOT(ISBLANK('FY2023 MEDEVAC Tracker'!#REF!)), 1, 0)))))))))) -> 10 | R10: =IF(IF(NOT(ISBLANK('FY2023 MEDEVAC Tracker'!$ED10)), 'FY2023 MEDEVAC Tracker'!$ED10-'FY2023 MEDEVAC Tracker'!#REF!, IF(NOT(ISBLANK('FY2023 MEDEVAC Tracker'!$DL10)), 'FY2023 MEDEVAC Tracker'!$DL10-'FY2023 MEDEVAC Tracker'!#REF!, IF(NOT(ISBLANK('FY2023 MEDEVAC Tracker'!$CT10)), 'FY2023 MEDEVAC Tracker'!$CT10-'FY2023 MEDEVAC Tracker'!#REF!, IF(NOT(ISBLANK('FY2023 MEDEVAC Tracker'!$CB10)), 'FY2023 MEDEVAC Tracker'!$CB10-'FY2023 MEDEVAC Tracker'!#REF!, IF(NOT(ISBLANK('FY2023 MEDEVAC Tracker'!$AO10)), 'FY2023 MEDEVAC Tracker'!$AO10-'FY2023 MEDEVAC Tracker'!#REF!, 0)))))<30, "0-30", IF(IF(NOT(ISBLANK('FY2023 MEDEVAC Tracker'!$ED10)), 'FY2023 MEDEVAC Tracker'!$ED10-'FY2023 MEDEVAC Tracker'!#REF!, IF(NOT(ISBLANK('FY2023 MEDEVAC Tracker'!$DL10)), 'FY2023 MEDEVAC Tracker'!$DL10-'FY2023 MEDEVAC Tracker'!#REF!, IF(NOT(ISBLANK('FY2023 MEDEVAC Tracker'!$CT10)), 'FY2023 MEDEVAC Tracker'!$CT10-'FY2023 MEDEVAC Tracker'!#REF!, IF(NOT(ISBLANK('FY2023 MEDEVAC Tracker'!$CB10)), 'FY2023 MEDEVAC Tracker'!$CB10-'FY2023 MEDEVAC Tracker'!#REF!, IF(NOT(ISBLANK('FY2023 MEDEVAC Tracker'!$AO10)), 'FY2023 MEDEVAC Tracker'!$AO10-'FY2023 MEDEVAC Tracker'!#REF!, 0)))))<60, "31-60", IF(IF(NOT(ISBLANK('FY2023 MEDEVAC Tracker'!$ED10)), 'FY2023 MEDEVAC Tracker'!$ED10-'FY2023 MEDEVAC Tracker'!#REF!, IF(NOT(ISBLANK('FY2023 MEDEVAC Tracker'!$DL10)), 'FY2023 MEDEVAC Tracker'!$DL10-'FY2023 MEDEVAC Tracker'!#REF!, IF(NOT(ISBLANK('FY2023 MEDEVAC Tracker'!$CT10)), 'FY2023 MEDEVAC Tracker'!$CT10-'FY2023 MEDEVAC Tracker'!#REF!, IF(NOT(ISBLANK('FY2023 MEDEVAC Tracker'!$CB10)), 'FY2023 MEDEVAC Tracker'!$CB10-'FY2023 MEDEVAC Tracker'!#REF!, IF(NOT(ISBLANK('FY2023 MEDEVAC Tracker'!$AO10)), 'FY2023 MEDEVAC Tracker'!$AO10-'FY2023 MEDEVAC Tracker'!#REF!, 0)))))<=90, "61-90", IF(IF(NOT(ISBLANK('FY2023 MEDEVAC Tracker'!$ED10)), 'FY2023 MEDEVAC Tracker'!$ED10-'FY2023 MEDEVAC Tracker'!#REF!, IF(NOT(ISBLANK('FY2023 MEDEVAC Tracker'!$DL10)), 'FY2023 MEDEVAC Tracker'!$DL10-'FY2023 MEDEVAC Tracker'!#REF!, IF(NOT(ISBLANK('FY2023 MEDEVAC Tracker'!$CT10)), 'FY2023 MEDEVAC Tracker'!$CT10-'FY2023 MEDEVAC Tracker'!#REF!, IF(NOT(ISBLANK('FY2023 MEDEVAC Tracker'!$CB10)), 'FY2023 MEDEVAC Tracker'!$CB10-'FY2023 MEDEVAC Tracker'!#REF!, IF(NOT(ISBLANK('FY2023 MEDEVAC Tracker'!$AO10)), 'FY2023 MEDEVAC Tracker'!$AO10-'FY2023 MEDEVAC Tracker'!#REF!, 0)))))>90, "91+", "N/A")))) -> 0-30 | U10: =_xlfn.DAYS('FY2023 MEDEVAC Tracker'!$T10,'FY2023 MEDEVAC Tracker'!$S10)+1 -> 1 | Z10: =IF(OR(ISBLANK('FY2023 MEDEVAC Tracker'!$W10), ISBLANK('FY2023 MEDEVAC Tracker'!$X10)), "N/A", (NETWORKDAYS('FY2023 MEDEVAC Tracker'!$W10,'FY2023 MEDEVAC Tracker'!$X10)+1)) -> N/A | AJ10: =('FY2023 MEDEVAC Tracker'!$AA10*[1]AH11Tracker!$AB10)+('FY2023 MEDEVAC Tracker'!$AC10*'FY2023 MEDEVAC Tracker'!$AD10)+('FY2023 MEDEVAC Tracker'!$AE10*'FY2023 MEDEVAC Tracker'!$AF10)+('FY2023 MEDEVAC Tracker'!$AG10*'FY2023 MEDEVAC Tracker'!$AH10) -> #REF! | AM10: ='FY2023 MEDEVAC Tracker'!$AJ10+'FY2023 MEDEVAC Tracker'!$AK10+'FY2023 MEDEVAC Tracker'!$AL10 -> #REF! | AN10: =AI10+AM10 -> #REF! | AT10: =IF(OR(ISBLANK('FY2023 MEDEVAC Tracker'!$AQ10), ISBLANK('FY2023 MEDEVAC Tracker'!$AR10)), "N/A",'FY2023 MEDEVAC Tracker'!$AR10-'FY2023 MEDEVAC Tracker'!$AQ10) -> N/A | BG10: =IF(ISBLANK('FY2023 MEDEVAC Tracker'!$BD10), 0, BD10-'FY2023 MEDEVAC Tracker'!$AI10) -> 0 | BH10: =MAX(0,IF(ISBLANK(AO10), 0, (((AV10*AW10)+(AX10*AY10)+(AZ10*BA10)+(BB10*BC10)+BE10+BF10)-AM10))) -> 0 | BI10: =IF(ISBLANK('FY2023 MEDEVAC Tracker'!$AO10), 0, SUM(AN10,BG10,BH10)) -> 0 | BN10: =IF(OR(ISBLANK('FY2023 MEDEVAC Tracker'!$BK10), ISBLANK('FY2023 MEDEVAC Tracker'!$BL10)), "N/A",'FY2023 MEDEVAC Tracker'!$BL10-'FY2023 MEDEVAC Tracker'!$BK10) -> N/A | BZ10: =((BP10*BQ10)+(BR10*BS10)+(BT10*BU10)+(BV10*BW10))+BY10 -> 0 | CA10: =BZ10+BX10 -> 0 | CF10: =IF(OR(ISBLANK('FY2023 MEDEVAC Tracker'!$CC10), ISBLANK('FY2023 MEDEVAC Tracker'!$CD10)), "N/A",'FY2023 MEDEVAC Tracker'!$CD10-'FY2023 MEDEVAC Tracker'!$CC10) -> N/A | CR10: =((CH10*CI10)+(CJ10*CK10)+(CL10*CM10)+(CN10*CO10))+CQ10 -> 0 | CS10: =CR10+CP10 -> 0 | CX10: =IF(OR(ISBLANK('FY2023 MEDEVAC Tracker'!$CU10), ISBLANK('FY2023 MEDEVAC Tracker'!$CV10)), "N/A",'FY2023 MEDEVAC Tracker'!$CV10-'FY2023 MEDEVAC Tracker'!$CU10) -> N/A | DJ10: =((CZ10*DA10)+(DB10*DC10)+(DD10*DE10)+(DF10*DG10))+DI10 -> 0 | DK10: =DJ10+DH10 -> 0 | DP10: =IF(OR(ISBLANK('FY2023 MEDEVAC Tracker'!$DM10), ISBLANK('FY2023 MEDEVAC Tracker'!$DN10)), "N/A",'FY2023 MEDEVAC Tracker'!$DN10-'FY2023 MEDEVAC Tracker'!$DM10) -> N/A | EB10: =((DR10*DS10)+(DT10*DU10)+(DV10*DW10)+(DX10*DY10))+EA10 -> 0 | EC10: =EB10+DZ10 -> 0 | EH10: =IF(OR(ISBLANK('FY2023 MEDEVAC Tracker'!$EE10), ISBLANK('FY2023 MEDEVAC Tracker'!$EF10)), "N/A",'FY2023 MEDEVAC Tracker'!$EF10-'FY2023 MEDEVAC Tracker'!$EE10) -> N/A | ET10: =((EJ10*EK10)+(EL10*EM10)+(EN10*EO10)+(EP10*EQ10))+ES10 -> 0 | EU10: =ET10+ER10 -> 0 | EZ10: =IF(OR(ISBLANK('FY2023 MEDEVAC Tracker'!$EE10), ISBLANK('FY2023 MEDEVAC Tracker'!$EF10)), "N/A",'FY2023 MEDEVAC Tracker'!$EF10-'FY2023 MEDEVAC Tracker'!$EE10) -> N/A | FL10: =((FT10*FU10)+(FV10*FW10)+(FF10*FG10)+(FH10*FI10))+FK10 -> 0 | FM10: =FL10+FJ10 -> 0 | FR10: =IF(OR(ISBLANK('FY2023 MEDEVAC Tracker'!$EE10), ISBLANK('FY2023 MEDEVAC Tracker'!$EF10)), "N/A",'FY2023 MEDEVAC Tracker'!$EF10-'FY2023 MEDEVAC Tracker'!$EE10) -> N/A | GE10: =GD10+GB10 -> 0 | GJ10: =IF(OR(ISBLANK('FY2023 MEDEVAC Tracker'!$GH10), ISBLANK('FY2023 MEDEVAC Tracker'!$GG10)), "N/A",'FY2023 MEDEVAC Tracker'!$GG10-'FY2023 MEDEVAC Tracker'!$GH10) -> N/A | GV10: =((GL10*GM10)+(GN10*GO10)+(GP10*GQ10)+(GR10*GS10))+GU10 -> 0 | GW10: =GV10+GT10 -> 0 | HB10: =IF(OR(ISBLANK('FY2023 MEDEVAC Tracker'!$GY10), ISBLANK('FY2023 MEDEVAC Tracker'!$GZ10)), "N/A",'FY2023 MEDEVAC Tracker'!#REF!-'FY2023 MEDEVAC Tracker'!#REF!) -> N/A | IJ10: =IF(ISBLANK('FY2023 MEDEVAC Tracker'!$AO10), 'FY2023 MEDEVAC Tracker'!$H10, 'FY2023 MEDEVAC Tracker'!$AO10) -> 0 | IK10: =MAX('FY2023 MEDEVAC Tracker'!$HP10, 'FY2023 MEDEVAC Tracker'!$GX10, 'FY2023 MEDEVAC Tracker'!$GF10, 'FY2023 MEDEVAC Tracker'!$FN10, 'FY2023 MEDEVAC Tracker'!$EV10, 'FY2023 MEDEVAC Tracker'!$ED10, 'FY2023 MEDEVAC Tracker'!$DL10, 'FY2023 MEDEVAC Tracker'!$CT10, 'FY2023 MEDEVAC Tracker'!$CB10, 'FY2023 MEDEVAC Tracker'!$BJ10, 'FY2023 MEDEVAC Tracker'!$AP10, 'FY2023 MEDEVAC Tracker'!$I10) -> 0 | IN10: =IM10+IL10 -> 0 | IO10: =G10-IN10 -> #REF!
B11: =IF(NOT(ISBLANK('FY2023 MEDEVAC Tracker'!$IH11)), IH11, IF(NOT(ISBLANK('FY2023 MEDEVAC Tracker'!$HR11)), "10th Extension Funding Out", IF(NOT(ISBLANK('FY2023 MEDEVAC Tracker'!$GZ11)), "9th Extension Funding Out", IF(NOT(ISBLANK('FY2023 MEDEVAC Tracker'!$GH11)), "8th Extension Funding Out", IF(NOT(ISBLANK('FY2023 MEDEVAC Tracker'!$FP11)), "7th Extension Funding Out", IF(NOT(ISBLANK('FY2023 MEDEVAC Tracker'!$EX11)), "6th Extension Funding Out", IF(NOT(ISBLANK('FY2023 MEDEVAC Tracker'!$EF11)), "5th Extension Funding Out", IF(NOT(ISBLANK('FY2023 MEDEVAC Tracker'!$EE11)), "5th Extension In Processing", IF(NOT(ISBLANK('FY2023 MEDEVAC Tracker'!$DN11)), "4th Extension Funding Out", IF(NOT(ISBLANK('FY2023 MEDEVAC Tracker'!$DM11)), "4th Extension In Processing",IF(NOT(ISBLANK('FY2023 MEDEVAC Tracker'!$CV11)), "3rd Extension Funding Out", IF(NOT(ISBLANK('FY2023 MEDEVAC Tracker'!$CU11)), "3rd Extension In Processing", IF(NOT(ISBLANK('FY2023 MEDEVAC Tracker'!$CD11)), "2nd Extension Funding Out", IF(NOT(ISBLANK('FY2023 MEDEVAC Tracker'!$CC11)), "2nd Extension In Processing", IF(NOT(ISBLANK('FY2023 MEDEVAC Tracker'!$BL11)), "1st Extension Funding Out", IF(NOT(ISBLANK('FY2023 MEDEVAC Tracker'!$BK11)), "1st Extension In Processing", IF(NOT(ISBLANK('FY2023 MEDEVAC Tracker'!$AR11)), "Amendment Funding Out", IF(NOT(ISBLANK('FY2023 MEDEVAC Tracker'!$AQ11)), "Amendment In Processing", IF(NOT(ISBLANK('FY2023 MEDEVAC Tracker'!$X11)), "Initial Funding Out", IF(NOT(ISBLANK('FY2023 MEDEVAC Tracker'!$W11)), "Initial In Processing", IF(NOT(ISBLANK('FY2023 MEDEVAC Tracker'!$W11)), "Initiated", "N/A"))))))))))))))))))))) -> N/A | D11: =_xlfn.NUMBERVALUE(CONCATENATE(RIGHT(YEAR((TODAY()-860)), 3), IF(OR('FY2023 MEDEVAC Tracker'!$E11="DOS", 'FY2023 MEDEVAC Tracker'!$E11="Seabee", 'FY2023 MEDEVAC Tracker'!$E11="DOS/Seabee"),10, 90), TEXT(((COUNTIF($E$8:E11, E11))-1),"000"))) -> #VALUE! | G11: =IF(ISBLANK('FY2023 MEDEVAC Tracker'!$AO11), 'FY2023 MEDEVAC Tracker'!$AN11, 'FY2023 MEDEVAC Tracker'!$BI11)+'FY2023 MEDEVAC Tracker'!$CA11+'FY2023 MEDEVAC Tracker'!$CS11+'FY2023 MEDEVAC Tracker'!$DK11+'FY2023 MEDEVAC Tracker'!$EC11+'FY2023 MEDEVAC Tracker'!$EU11+'FY2023 MEDEVAC Tracker'!$FM11+'FY2023 MEDEVAC Tracker'!$GE11+'FY2023 MEDEVAC Tracker'!$GW11+'FY2023 MEDEVAC Tracker'!$HO11+'FY2023 MEDEVAC Tracker'!$IG11 -> #REF! | H11: =IF(ISBLANK('FY2023 MEDEVAC Tracker'!$AO11), 'FY2023 MEDEVAC Tracker'!$S11, 'FY2023 MEDEVAC Tracker'!$AO11) -> 0 | I11: =MAX('FY2023 MEDEVAC Tracker'!$T11, 'FY2023 MEDEVAC Tracker'!$AP11, 'FY2023 MEDEVAC Tracker'!$BJ11, 'FY2023 MEDEVAC Tracker'!$CB11, 'FY2023 MEDEVAC Tracker'!$CT11, 'FY2023 MEDEVAC Tracker'!$DL11, 'FY2023 MEDEVAC Tracker'!$ED11, 'FY2023 MEDEVAC Tracker'!$EV11, 'FY2023 MEDEVAC Tracker'!$FN11, 'FY2023 MEDEVAC Tracker'!$GF11, 'FY2023 MEDEVAC Tracker'!$GX11, 'FY2023 MEDEVAC Tracker'!$HP11, ) -> 0 | M11: =VLOOKUP('FY2023 MEDEVAC Tracker'!$N11, List!F:H, 3, FALSE) -> #N/A | O11: =IF(NOT(ISBLANK('FY2023 MEDEVAC Tracker'!$HU11)), 'FY2023 MEDEVAC Tracker'!$HU11, IF(NOT(ISBLANK('FY2023 MEDEVAC Tracker'!$HC11)), 'FY2023 MEDEVAC Tracker'!$HC11, IF(NOT(ISBLANK('FY2023 MEDEVAC Tracker'!$GK11)), 'FY2023 MEDEVAC Tracker'!$GK11, IF(NOT(ISBLANK('FY2023 MEDEVAC Tracker'!$FS11)), 'FY2023 MEDEVAC Tracker'!$FS11, IF(NOT(ISBLANK('FY2023 MEDEVAC Tracker'!$FA11)), 'FY2023 MEDEVAC Tracker'!$FA11, IF(NOT(ISBLANK('FY2023 MEDEVAC Tracker'!$EI11)), 'FY2023 MEDEVAC Tracker'!$EI11, IF(NOT(ISBLANK('FY2023 MEDEVAC Tracker'!$DQ11)), 'FY2023 MEDEVAC Tracker'!$DQ11, IF(NOT(ISBLANK('FY2023 MEDEVAC Tracker'!$CY11)), 'FY2023 MEDEVAC Tracker'!$CY11, IF(NOT(ISBLANK('FY2023 MEDEVAC Tracker'!$CG11)), 'FY2023 MEDEVAC Tracker'!$CG11, IF(NOT(ISBLANK('FY2023 MEDEVAC Tracker'!$BO11)), 'FY2023 MEDEVAC Tracker'!$BO11, IF(NOT(ISBLANK('FY2023 MEDEVAC Tracker'!$AU11)), 'FY2023 MEDEVAC Tracker'!$AU11, IF(NOT(ISBLANK('FY2023 MEDEVAC Tracker'!$V11)), 'FY2023 MEDEVAC Tracker'!$V11, 'FY2023 MEDEVAC Tracker'!$V11)))))))))))) -> 0 | Q11: =IF(NOT(ISBLANK('FY2023 MEDEVAC Tracker'!#REF!)), 10, IF(NOT(ISBLANK('FY2023 MEDEVAC Tracker'!#REF!)), 9, IF(NOT(ISBLANK('FY2023 MEDEVAC Tracker'!#REF!)), 8, IF(NOT(ISBLANK('FY2023 MEDEVAC Tracker'!#REF!)), 7, IF(NOT(ISBLANK('FY2023 MEDEVAC Tracker'!#REF!)), 6, IF(NOT(ISBLANK('FY2023 MEDEVAC Tracker'!#REF!)), 5, IF(NOT(ISBLANK('FY2023 MEDEVAC Tracker'!#REF!)), 4, IF(NOT(ISBLANK('FY2023 MEDEVAC Tracker'!#REF!)), 3, IF(NOT(ISBLANK('FY2023 MEDEVAC Tracker'!#REF!)), 2, IF(NOT(ISBLANK('FY2023 MEDEVAC Tracker'!#REF!)), 1, 0)))))))))) -> 10 | R11: =IF(IF(NOT(ISBLANK('FY2023 MEDEVAC Tracker'!$ED11)), 'FY2023 MEDEVAC Tracker'!$ED11-'FY2023 MEDEVAC Tracker'!#REF!, IF(NOT(ISBLANK('FY2023 MEDEVAC Tracker'!$DL11)), 'FY2023 MEDEVAC Tracker'!$DL11-'FY2023 MEDEVAC Tracker'!#REF!, IF(NOT(ISBLANK('FY2023 MEDEVAC Tracker'!$CT11)), 'FY2023 MEDEVAC Tracker'!$CT11-'FY2023 MEDEVAC Tracker'!#REF!, IF(NOT(ISBLANK('FY2023 MEDEVAC Tracker'!$CB11)), 'FY2023 MEDEVAC Tracker'!$CB11-'FY2023 MEDEVAC Tracker'!#REF!, IF(NOT(ISBLANK('FY2023 MEDEVAC Tracker'!$AO11)), 'FY2023 MEDEVAC Tracker'!$AO11-'FY2023 MEDEVAC Tracker'!#REF!, 0)))))<30, "0-30", IF(IF(NOT(ISBLANK('FY2023 MEDEVAC Tracker'!$ED11)), 'FY2023 MEDEVAC Tracker'!$ED11-'FY2023 MEDEVAC Tracker'!#REF!, IF(NOT(ISBLANK('FY2023 MEDEVAC Tracker'!$DL11)), 'FY2023 MEDEVAC Tracker'!$DL11-'FY2023 MEDEVAC Tracker'!#REF!, IF(NOT(ISBLANK('FY2023 MEDEVAC Tracker'!$CT11)), 'FY2023 MEDEVAC Tracker'!$CT11-'FY2023 MEDEVAC Tracker'!#REF!, IF(NOT(ISBLANK('FY2023 MEDEVAC Tracker'!$CB11)), 'FY2023 MEDEVAC Tracker'!$CB11-'FY2023 MEDEVAC Tracker'!#REF!, IF(NOT(ISBLANK('FY2023 MEDEVAC Tracker'!$AO11)), 'FY2023 MEDEVAC Tracker'!$AO11-'FY2023 MEDEVAC Tracker'!#REF!, 0)))))<60, "31-60", IF(IF(NOT(ISBLANK('FY2023 MEDEVAC Tracker'!$ED11)), 'FY2023 MEDEVAC Tracker'!$ED11-'FY2023 MEDEVAC Tracker'!#REF!, IF(NOT(ISBLANK('FY2023 MEDEVAC Tracker'!$DL11)), 'FY2023 MEDEVAC Tracker'!$DL11-'FY2023 MEDEVAC Tracker'!#REF!, IF(NOT(ISBLANK('FY2023 MEDEVAC Tracker'!$CT11)), 'FY2023 MEDEVAC Tracker'!$CT11-'FY2023 MEDEVAC Tracker'!#REF!, IF(NOT(ISBLANK('FY2023 MEDEVAC Tracker'!$CB11)), 'FY2023 MEDEVAC Tracker'!$CB11-'FY2023 MEDEVAC Tracker'!#REF!, IF(NOT(ISBLANK('FY2023 MEDEVAC Tracker'!$AO11)), 'FY2023 MEDEVAC Tracker'!$AO11-'FY2023 MEDEVAC Tracker'!#REF!, 0)))))<=90, "61-90", IF(IF(NOT(ISBLANK('FY2023 MEDEVAC Tracker'!$ED11)), 'FY2023 MEDEVAC Tracker'!$ED11-'FY2023 MEDEVAC Tracker'!#REF!, IF(NOT(ISBLANK('FY2023 MEDEVAC Tracker'!$DL11)), 'FY2023 MEDEVAC Tracker'!$DL11-'FY2023 MEDEVAC Tracker'!#REF!, IF(NOT(ISBLANK('FY2023 MEDEVAC Tracker'!$CT11)), 'FY2023 MEDEVAC Tracker'!$CT11-'FY2023 MEDEVAC Tracker'!#REF!, IF(NOT(ISBLANK('FY2023 MEDEVAC Tracker'!$CB11)), 'FY2023 MEDEVAC Tracker'!$CB11-'FY2023 MEDEVAC Tracker'!#REF!, IF(NOT(ISBLANK('FY2023 MEDEVAC Tracker'!$AO11)), 'FY2023 MEDEVAC Tracker'!$AO11-'FY2023 MEDEVAC Tracker'!#REF!, 0)))))>90, "91+", "N/A")))) -> 0-30 | U11: =_xlfn.DAYS('FY2023 MEDEVAC Tracker'!$T11,'FY2023 MEDEVAC Tracker'!$S11)+1 -> 1 | Z11: =IF(OR(ISBLANK('FY2023 MEDEVAC Tracker'!$W11), ISBLANK('FY2023 MEDEVAC Tracker'!$X11)), "N/A", (NETWORKDAYS('FY2023 MEDEVAC Tracker'!$W11,'FY2023 MEDEVAC Tracker'!$X11)+1)) -> N/A | AJ11: =('FY2023 MEDEVAC Tracker'!$AA11*[1]AH11Tracker!$AB11)+('FY2023 MEDEVAC Tracker'!$AC11*'FY2023 MEDEVAC Tracker'!$AD11)+('FY2023 MEDEVAC Tracker'!$AE11*'FY2023 MEDEVAC Tracker'!$AF11)+('FY2023 MEDEVAC Tracker'!$AG11*'FY2023 MEDEVAC Tracker'!$AH11) -> #REF! | AM11: ='FY2023 MEDEVAC Tracker'!$AJ11+'FY2023 MEDEVAC Tracker'!$AK11+'FY2023 MEDEVAC Tracker'!$AL11 -> #REF! | AN11: =AI11+AM11 -> #REF! | AT11: =IF(OR(ISBLANK('FY2023 MEDEVAC Tracker'!$AQ11), ISBLANK('FY2023 MEDEVAC Tracker'!$AR11)), "N/A",'FY2023 MEDEVAC Tracker'!$AR11-'FY2023 MEDEVAC Tracker'!$AQ11) -> N/A | BG11: =IF(ISBLANK('FY2023 MEDEVAC Tracker'!$BD11), 0, BD11-'FY2023 MEDEVAC Tracker'!$AI11) -> 0 | BH11: =MAX(0,IF(ISBLANK(AO11), 0, (((AV11*AW11)+(AX11*AY11)+(AZ11*BA11)+(BB11*BC11)+BE11+BF11)-AM11))) -> 0 | BI11: =IF(ISBLANK('FY2023 MEDEVAC Tracker'!$AO11), 0, SUM(AN11,BG11,BH11)) -> 0 | BN11: =IF(OR(ISBLANK('FY2023 MEDEVAC Tracker'!$BK11), ISBLANK('FY2023 MEDEVAC Tracker'!$BL11)), "N/A",'FY2023 MEDEVAC Tracker'!$BL11-'FY2023 MEDEVAC Tracker'!$BK11) -> N/A | BZ11: =((BP11*BQ11)+(BR11*BS11)+(BT11*BU11)+(BV11*BW11))+BY11 -> 0 | CA11: =BZ11+BX11 -> 0 | CF11: =IF(OR(ISBLANK('FY2023 MEDEVAC Tracker'!$CC11), ISBLANK('FY2023 MEDEVAC Tracker'!$CD11)), "N/A",'FY2023 MEDEVAC Tracker'!$CD11-'FY2023 MEDEVAC Tracker'!$CC11) -> N/A | CR11: =((CH11*CI11)+(CJ11*CK11)+(CL11*CM11)+(CN11*CO11))+CQ11 -> 0 | CS11: =CR11+CP11 -> 0 | CX11: =IF(OR(ISBLANK('FY2023 MEDEVAC Tracker'!$CU11), ISBLANK('FY2023 MEDEVAC Tracker'!$CV11)), "N/A",'FY2023 MEDEVAC Tracker'!$CV11-'FY2023 MEDEVAC Tracker'!$CU11) -> N/A | DJ11: =((CZ11*DA11)+(DB11*DC11)+(DD11*DE11)+(DF11*DG11))+DI11 -> 0 | DK11: =DJ11+DH11 -> 0 | DP11: =IF(OR(ISBLANK('FY2023 MEDEVAC Tracker'!$DM11), ISBLANK('FY2023 MEDEVAC Tracker'!$DN11)), "N/A",'FY2023 MEDEVAC Tracker'!$DN11-'FY2023 MEDEVAC Tracker'!$DM11) -> N/A | EB11: =((DR11*DS11)+(DT11*DU11)+(DV11*DW11)+(DX11*DY11))+EA11 -> 0 | EC11: =EB11+DZ11 -> 0 | EH11: =IF(OR(ISBLANK('FY2023 MEDEVAC Tracker'!$EE11), ISBLANK('FY2023 MEDEVAC Tracker'!$EF11)), "N/A",'FY2023 MEDEVAC Tracker'!$EF11-'FY2023 MEDEVAC Tracker'!$EE11) -> N/A | ET11: =((EJ11*EK11)+(EL11*EM11)+(EN11*EO11)+(EP11*EQ11))+ES11 -> 0 | EU11: =ET11+ER11 -> 0 | EZ11: =IF(OR(ISBLANK('FY2023 MEDEVAC Tracker'!$EE11), ISBLANK('FY2023 MEDEVAC Tracker'!$EF11)), "N/A",'FY2023 MEDEVAC Tracker'!$EF11-'FY2023 MEDEVAC Tracker'!$EE11) -> N/A | FL11: =((FT11*FU11)+(FV11*FW11)+(FF11*FG11)+(FH11*FI11))+FK11 -> 0 | FM11: =FL11+FJ11 -> 0 | FR11: =IF(OR(ISBLANK('FY2023 MEDEVAC Tracker'!$EE11), ISBLANK('FY2023 MEDEVAC Tracker'!$EF11)), "N/A",'FY2023 MEDEVAC Tracker'!$EF11-'FY2023 MEDEVAC Tracker'!$EE11) -> N/A | GE11: =GD11+GB11 -> 0 | GJ11: =IF(OR(ISBLANK('FY2023 MEDEVAC Tracker'!$GH11), ISBLANK('FY2023 MEDEVAC Tracker'!$GG11)), "N/A",'FY2023 MEDEVAC Tracker'!$GG11-'FY2023 MEDEVAC Tracker'!$GH11) -> N/A | GV11: =((GL11*GM11)+(GN11*GO11)+(GP11*GQ11)+(GR11*GS11))+GU11 -> 0 | GW11: =GV11+GT11 -> 0 | HB11: =IF(OR(ISBLANK('FY2023 MEDEVAC Tracker'!$GY11), ISBLANK('FY2023 MEDEVAC Tracker'!$GZ11)), "N/A",'FY2023 MEDEVAC Tracker'!#REF!-'FY2023 MEDEVAC Tracker'!#REF!) -> N/A | IJ11: =IF(ISBLANK('FY2023 MEDEVAC Tracker'!$AO11), 'FY2023 MEDEVAC Tracker'!$H11, 'FY2023 MEDEVAC Tracker'!$AO11) -> 0 | IK11: =MAX('FY2023 MEDEVAC Tracker'!$HP11, 'FY2023 MEDEVAC Tracker'!$GX11, 'FY2023 MEDEVAC Tracker'!$GF11, 'FY2023 MEDEVAC Tracker'!$FN11, 'FY2023 MEDEVAC Tracker'!$EV11, 'FY2023 MEDEVAC Tracker'!$ED11, 'FY2023 MEDEVAC Tracker'!$DL11, 'FY2023 MEDEVAC Tracker'!$CT11, 'FY2023 MEDEVAC Tracker'!$CB11, 'FY2023 MEDEVAC Tracker'!$BJ11, 'FY2023 MEDEVAC Tracker'!$AP11, 'FY2023 MEDEVAC Tracker'!$I11) -> 0 | IN11: =IM11+IL11 -> 0 | IO11: =G11-IN11 -> #REF!
